Workbook

Sheet データ
B1: 45748 | C1: =TEXT(B1,"YYYY-mm-dd") -> 2025-04-01
B2: TUKAN_DATE | C2: TUKAN_NUM | D2: SYOYUSYA_CODE | E2: SURY | F2: TUKAN_KING | G2: GENRYO_CODE | H2: 列1 | I2: 列2
B3: 45762 | C3: 81201516750 | D3: 2 | E3: 315000 | F3: 12118704 | G3: 2000 | H3: =IF(C3=C2,"",COUNTIF(G3,1000)+COUNTIF(G3,2000)) -> 1 | I3: =IF(H3=0,"",IF(C3=C2,"",SUM($H$3:H3))) -> 1 | L3: =IF(C3=C2,"",COUNTIF(G3,1000)+COUNTIF(G3,2000))
B4: 45762 | C4: 81201516750 | D4: 2 | E4: 315000 | F4: 12118704 | G4: 2000 | H4: =IF(C4=C3,"",COUNTIF(G4,1000)+COUNTIF(G4,2000)) | I4: =IF(H4=0,"",IF(C4=C3,"",SUM($H$3:H4))) | L4: =IF(H3=0,"",IF(C3=C2,"",SUM($H$3:H3)))
B5: 45762 | C5: 81201516750 | D5: 2 | E5: 315000 | F5: 12118704 | G5: 2000 | H5: =IF(C5=C4,"",COUNTIF(G5,1000)+COUNTIF(G5,2000)) | I5: =IF(H5=0,"",IF(C5=C4,"",SUM($H$3:H5)))
B6: 45762 | C6: 81201516750 | D6: 2 | E6: 315000 | F6: 12118704 | G6: 2000 | H6: =IF(C6=C5,"",COUNTIF(G6,1000)+COUNTIF(G6,2000)) | I6: =IF(H6=0,"",IF(C6=C5,"",SUM($H$3:H6)))
B7: 45762 | C7: 81201516750 | D7: 2 | E7: 315000 | F7: 12118704 | G7: 2000 | H7: =IF(C7=C6,"",COUNTIF(G7,1000)+COUNTIF(G7,2000)) | I7: =IF(H7=0,"",IF(C7=C6,"",SUM($H$3:H7)))
B8: 45762 | C8: 81201516750 | D8: 2 | E8: 315000 | F8: 12118704 | G8: 2000 | H8: =IF(C8=C7,"",COUNTIF(G8,1000)+COUNTIF(G8,2000)) | I8: =IF(H8=0,"",IF(C8=C7,"",SUM($H$3:H8)))
B9: 45762 | C9: 81201516750 | D9: 2 | E9: 315000 | F9: 12118704 | G9: 2000 | H9: =IF(C9=C8,"",COUNTIF(G9,1000)+COUNTIF(G9,2000)) | I9: =IF(H9=0,"",IF(C9=C8,"",SUM($H$3:H9)))
B10: 45762 | C10: 81201516750 | D10: 2 | E10: 315000 | F10: 12118704 | G10: 2000 | H10: =IF(C10=C9,"",COUNTIF(G10,1000)+COUNTIF(G10,2000)) | I10: =IF(H10=0,"",IF(C10=C9,"",SUM($H$3:H10)))
B11: 45762 | C11: 81201516750 | D11: 2 | E11: 315000 | F11: 12118704 | G11: 2000 | H11: =IF(C11=C10,"",COUNTIF(G11,1000)+COUNTIF(G11,2000)) | I11: =IF(H11=0,"",IF(C11=C10,"",SUM($H$3:H11)))
B12: 45762 | C12: 81201516750 | D12: 2 | E12: 315000 | F12: 12118704 | G12: 2000 | H12: =IF(C12=C11,"",COUNTIF(G12,1000)+COUNTIF(G12,2000)) | I12: =IF(H12=0,"",IF(C12=C11,"",SUM($H$3:H12)))
B13: 45762 | C13: 81201516750 | D13: 2 | E13: 315000 | F13: 12118704 | G13: 2000 | H13: =IF(C13=C12,"",COUNTIF(G13,1000)+COUNTIF(G13,2000)) | I13: =IF(H13=0,"",IF(C13=C12,"",SUM($H$3:H13)))
B14: 45762 | C14: 81201516750 | D14: 2 | E14: 315000 | F14: 12118704 | G14: 2000 | H14: =IF(C14=C13,"",COUNTIF(G14,1000)+COUNTIF(G14,2000)) | I14: =IF(H14=0,"",IF(C14=C13,"",SUM($H$3:H14)))
B15: 45762 | C15: 81201516750 | D15: 2 | E15: 315000 | F15: 12118704 | G15: 2000 | H15: =IF(C15=C14,"",COUNTIF(G15,1000)+COUNTIF(G15,2000)) | I15: =IF(H15=0,"",IF(C15=C14,"",SUM($H$3:H15)))
B16: 45762 | C16: 81201516750 | D16: 2 | E16: 315000 | F16: 12118704 | G16: 2000 | H16: =IF(C16=C15,"",COUNTIF(G16,1000)+COUNTIF(G16,2000)) | I16: =IF(H16=0,"",IF(C16=C15,"",SUM($H$3:H16)))
... B913: 45888 | C913: 81203863040 | D913: 2 | E913: 2080000 | F913: 71776677 | G913: 1000 | H913: =IF(C913=C912,"",COUNTIF(G913,1000)+COUNTIF(G913,2000)) | I913: =IF(H913=0,"",IF(C913=C912,"",SUM($H$3:H913)))

Sheet 輸入品消費税（日和産業）
A4: 請 求 書
J7: NO. | L7: 250803 | N7: ⇐ No 請求書明細.ｘｌｓ より
J8: 45900 | N8: ⇐ 対象月の末日
C11: 日和産業株式会社 八戸工場 | F11: 御中
J14: TEL | L14: (0178)21-3353(代表)
J15: FAX | L15: (0178)29-1300
C17: 下記の通り御請求申し上げます
B20: 月 | C20: 日 | D20: 品 名 | E20: 区分 | F20: 数量 | H20: 総量（kg） | J20: 単 価 | L20: 金 額（円）
B21: 8月分 | D21: 輸入品消費税 | N21: 3月分
B22: 8 | C22: 8 | D22: INDIGO SW (通関No.81203721200 ） | E22: 大麦 | H22: 90000 | L22: 355500 | N22: down | R22: 45414 | S22: メイズ | T22: 81195303000 | U22: GRACE
C23: 19 | D23: BESKIDY (通関No.81203863040 ） | E23: メイズ | H23: 700000 | L23: 2415500 | R23: 45425 | S23: 大麦 | T23: 81195475640 | U23: NEW NOBLE
R24: 45429 | S24: メイズ | T24: 81195629420 | U24: SAUVAN
R25: 45433 | S25: 大麦 | T25: 81195674550 | U25: RUBY CONFIDENCE
R26: 45435 | S26: 大麦 | T26: 81195746100 | U26: RUBY CONFIDENCE
B32: 合 計 | H32: =SUM(H21:H31) -> 790000 | I32: kg | L32: =SUM(L22:L31) -> 2771000
B34: 取引銀行 青森みちのく銀行八戸中央支店(普)2005721 | H34: 延長後の納期限： | K34: 45992 | N34: ⇐ 請求日から３か月後の月末（休日の時は翌営業日）
H40: =SUM(H22:H31) -> 790000 | L40: =SUM(L22:L30) -> 2771000

Sheet 輸入品消費税（日清丸紅
A4: 請 求 書
J7: NO. | L7: ='輸入品消費税（日和産業）'!L7+1 -> 250804
J8: ='輸入品消費税（日和産業）'!J8:L8 -> 45900
C12: 日清丸紅飼料株式会社 | E12: 御中
J15: TEL | L15: (0178)21-3353(代表)
J16: FAX | L16: (0178)29-1300
C18: 下記の通り御請求申し上げます
B21: 月 | C21: 日 | D21: 品 名 | E21: 区分 | F21: 数量 | H21: 総量（kg） | J21: 単 価 | L21: 金 額（円）
B22: ='輸入品消費税（日和産業）'!B21:C21 -> 8月分 | D22: 輸入品消費税 | N22: 24/8月
B23: 8 | C23: 6 | D23: INDIGO SW (通関No.81203687010 ） | E23: 大麦 | H23: 675450 | L23: 2660200 | N23: down
C24: 19 | D24: BESKIDY (通関No.81203863040 ） | E24: メイズ | H24: 500000 | L24: 1725400 | S24: 45433 | T24: 大麦 | U24: 81195674550 | V24: RUBY CONFIDENCE
B33: 合 計 | H33: =SUM(H22:H32) -> 1175450 | I33: kg | L33: =SUM(L23:L32) -> 4385600
B35: 取引銀行 青森みちのく銀行八戸中央支店(普)2005721 | H35: 延長後の納期限： | K35: ='輸入品消費税（日和産業）'!K34:L34 -> 45992
H38: =SUM(H23:H28) -> 1175450 | L38: =SUM(L23:L28) -> 4385600

Sheet 合計
A1: ='輸入品消費税（日和産業）'!B22 -> 8
B2: ='輸入品消費税（日和産業）'!L32+'輸入品消費税（日清丸紅'!L33 -> 7156600
D4: 4306000 | E4: ←仮払い消費税（雪印）月計を入力してください
D5: =SUM(B2:D4) -> 11462600 | E5: ←輸入品消費税 担保残高.xls で月合計を確認してください
B7: 未払金残高 | C7: 支払い期限 | D7: 支払い日 | E7: 仮払い消費税 | F7: 未収入金
A8: 4月 | B8: 14353400 | C8: 44775 | D8: 44775 | E8: 3719100 | F8: =B8-E8 -> 10634300
A9: 5月 | B9: 10092400 | C9: 44804 | D9: 44803 | E9: 2905600 | F9: =B9-E9 -> 7186800
A10: 6月 | B10: 10057600 | C10: 44834 | D10: 44834 | E10: 4211100 | F10: =B10-E10 -> 5846500
A11: 7月 | B11: 9136100 | C11: 44866 | D11: 44848 | E11: 2076200 | F11: =B11-E11 -> 7059900
A12: 8月 | B12: 11482600 | C12: 44895 | D12: 44873 | E12: 2356600 | F12: =B12-E12 -> 9126000
A13: 9月 | B13: 9902000 | C13: 44565 | D13: 44894 | E13: 3755000 | F13: =B13-E13 -> 6147000
A14: 10月 | B14: 12136500 | C14: 44592 | D14: 44917 | E14: 3333700 | F14: =B14-E14 -> 8802800
A15: 11月 | B15: 15795100 | C15: 44255 | D15: 44586 | E15: 2930100 | F15: =B15-E15 -> 12865000
A16: 12月 | B16: 12973600 | C16: 44286 | D16: 44617 | E16: 3885850 | F16: =B16-E16 -> 9087750
A17: 1月 | B17: 16110300 | C17: 44683 | D17: 44683 | E17: 4471000 | F17: =B17-E17 -> 11639300
A18: 2月 | B18: 9960200 | C18: 44712 | D18: 44712 | E18: 3832300 | F18: =B18-E18 -> 6127900
A19: 3月 | B19: 9936400 | C19: 44742 | D19: 44742 | E19: 2670000 | F19: =B19-E19 -> 7266400
... A22: 6月 | B22: 14149200 | C22: 44834 | D22: 44834 | E22: 6021200 | F22: =B22-E22 -> 8128000
A23: 7月 | B23: 9653900 | C23: 44865 | D23: 44865 | E23: 0 | F23: 9653900
A24: 8月 | B24: 21066400 | C24: 44895 | D24: 44890 | E24: 7721500 | F24: 13344900
A25: 9月 | B25: 21087800 | C25: 44930 | D25: 44930 | E25: 4510550 | F25: 16577250
A26: 10月 | B26: 19440300 | C26: 44957 | D26: 44957 | E26: 5215300 | F26: 14225000
A27: 11月 | B27: =E27+F27 -> 23351700 | C27: 44985 | D27: 44985 | E27: 4626000 | F27: 18725700
A28: 12月 | B28: =E28+F28 -> 18351100 | C28: 44286 | D28: 45016 | E28: 5917100 | F28: 12434000
A29: 1月 | B29: =E29+F29 -> 16881600 | C29: 45047 | D29: 45047 | E29: 4940000 | F29: 11941600
A30: 2月 | B30: =E30+F30 -> 14825900 | C30: 45077 | D30: 45077 | E30: 3502600 | F30: 11323300
A31: 3月 | B31: =E31+F31 -> 20484600 | C31: 45107 | D31: 45107 | E31: 5852300 | F31: 14632300
A32: 4月 | B32: =E32+F32 -> 12920000 | C32: 45138 | D32: 45138 | E32: 4110700 | F32: 8809300
A33: 5月 | B33: =E33+F33 -> 8695800 | C33: 45169 | D33: 45169 | E33: 4406400 | F33: 4289400
A34: 6月 | B34: =E34+F34 -> 20437000 | C34: 45201 | D34: 45201 | E34: 6651900 | F34: 13785100
A35: 7月 | B35: =E35+F35 -> 15875600 | C35: 45230 | D35: 45225 | E35: 5951200 | F35: 9924400
A36: 8月 | B36: =E36+F36 -> 13859400 | C36: 45260 | D36: 45260 | E36: 3544800 | F36: 10314600
A37: 9月 | B37: =E37+F37 -> 16842200 | C37: 45295 | D37: 45295 | E37: 3431900 | F37: 13410300
A38: 10月 | B38: =E38+F38 -> 17220900 | C38: 45322 | D38: 45322 | E38: 4761600 | F38: 12459300
... A52: 12月 | B52: =E52+F52 -> 13750600 | C52: 45747 | D52: 45747 | E52: 3017400 | F52: 10733200
A53: 1月 | B53: =E53+F53+3700 -> 8165000 | C53: 45777 | D53: 45777 | E53: 2313200 | F53: 5848100
A54: 2月 | B54: =E54+F54 -> 9290000 | C54: 45810 | D54: 45810 | E54: 3571300 | F54: 5718700
A55: 3月 | B55: =E55+F55-3700 -> 11875700 | C55: 45838 | D55: 45838 | E55: 3964400 | F55: 7915000
A56: 4月 | B56: =E56+F56 -> 8123200 | C56: 45869 | D56: 45863 | E56: 4709700 | F56: 3413500
A57: 5月 | B57: =E57+F57 -> 11522700 | C57: 45901 | D57: 45897 | E57: 3068000 | F57: 8454700
...

Sheet 消費税負担分2025
B3: 対象年月 | C3: 通関年月日 | D3: 原料名 | E3: 通関NO | F3: 全体数量 （MT） | G3: 単価/ｔ | H3: 申告価格 | I3: 消費税計算用 （100円以下切捨て） | J3: 消費税額 | K3: D関税 | L3: F消費税 （7.8％） | M3: A地方消費税 （22/78） | N3: B負担分 数量 （MT） | O3: 負担分の 申告価格 割り返し | P3: ①消費税 （7.8％） | Q3: ②地方消費税 （22/78） | R3: 消費税 負担額
A4: 1 | B4: 202504 | C4: =SUMIF(データ!I:I,A4,データ!B:B) -> 45762 | D4: 大麦 | E4: =_xlfn.XLOOKUP(A4,データ!I:I,データ!C:C,"") -> 81201516750 | F4: 315 | G4: =H4/F4 -> 38472.076 | H4: 12118704 | I4: =FLOOR(H4,1000) -> 12118000 | J4: 1211700 | K4: 0 | L4: =ROUNDDOWN(I4*7.8/100,-2) -> 945200 | M4: =J4-L4 -> 266500 | N4: 315 | O4: =ROUND(I4/F4*N4,-2) -> 12118000 | P4: =ROUNDDOWN(O4*7.8/100,-2) -> 945200 | Q4: =R4-P4 -> 266500 | R4: 1211700
A5: =A4+1 -> 2 | B5: 202504 | C5: 45762 | D5: メイズ | E5: 81201517600 | F5: 950 | G5: =H5/F5 -> 39036.256 | H5: 37084443 | I5: =FLOOR(H5,1000) -> 37084000 | J5: 3708300 | K5: 0 | L5: =ROUNDDOWN(I5*7.8/100,-2) -> 2892500 | M5: =J5-L5 -> 815800 | N5: 500 | O5: =ROUND(I5/F5*N5,-2) -> 19517900 | P5: =ROUNDDOWN(O5*7.8/100,-2) -> 1522300 | Q5: =R5-P5 -> 429400 | R5: 1951700
A6: =A5+1 -> 3 | B6: 202504 | C6: 45777 | D6: メイズ | E6: 81201793250 | F6: 870 | G6: =H6/F6 -> 36820.077 | H6: 32033467 | I6: =FLOOR(H6,1000) -> 32033000 | J6: 3203200 | K6: 0 | L6: =ROUNDDOWN(I6*7.8/100,-2) -> 2498500 | M6: =J6-L6 -> 704700 | N6: 420 | O6: =ROUND(I6/F6*N6,-2) -> 15464200 | P6: =ROUNDDOWN(O6*7.8/100,-2) -> 1206200 | Q6: =R6-P6 -> 340100 | R6: 1546300
A7: =A6+1 -> 4 | B7: 202505 | C7: 45798 | D7: メイズ | E7: 81202182930 | F7: 810 | G7: =H7/F7 -> 37878.083 | H7: 30681247 | I7: =FLOOR(H7,1000) -> 30681000 | J7: 3068000 | K7: 0 | L7: =ROUNDDOWN(I7*7.8/100,-2) -> 2393100 | M7: =J7-L7 -> 674900 | N7: 810 | O7: =ROUND(I7/F7*N7,-2) -> 30681000 | P7: =ROUNDDOWN(O7*7.8/100,-2) -> 2393100 | Q7: =R7-P7 -> 674900 | R7: 3068000
A8: =A7+1 -> 5 | B8: 202505 | C8: 45799 | D8: 大麦 | E8: 81202213510 | F8: 533.68 | G8: =H8/F8 -> 38155.194 | H8: 20362664 | I8: =FLOOR(H8,1000) -> 20362000 | J8: 2036100 | K8: 0 | L8: =ROUNDDOWN(I8*7.8/100,-2) -> 1588200 | M8: =J8-L8 -> 447900 | N8: 0 | O8: =ROUND(I8/F8*N8,-2) -> 0 | P8: =ROUNDDOWN(O8*7.8/100,-2) -> 0 | Q8: =R8-P8 -> 0 | R8: 0
A9: =A8+1 -> 6 | B9: 202505 | C9: 45800 | D9: メイズ | E9: 81202223160 | F9: 350 | G9: =H9/F9 -> 37878.08 | H9: 13257328 | I9: =FLOOR(H9,1000) -> 13257000 | J9: 1325600 | K9: 0 | L9: =ROUNDDOWN(I9*7.8/100,-2) -> 1034000 | M9: =J9-L9 -> 291600 | N9: 0 | O9: =ROUND(I9/F9*N9,-2) -> 0 | P9: =ROUNDDOWN(O9*7.8/100,-2) -> 0 | Q9: =R9-P9 -> 0 | R9: 0
A10: =A9+1 -> 7 | B10: 202505 | C10: 45804 | D10: 大麦 | E10: 81202285940 | F10: 100 | G10: =H10/F10 -> 38744.95 | H10: 3874495 | I10: =FLOOR(H10,1000) -> 3874000 | J10: 387300 | K10: 0 | L10: =ROUNDDOWN(I10*7.8/100,-2) -> 302100 | M10: =J10-L10 -> 85200 | N10: 0 | O10: =ROUND(I10/F10*N10,-2) -> 0 | P10: =ROUNDDOWN(O10*7.8/100,-2) -> 0 | Q10: =R10-P10 -> 0 | R10: 0
A11: =A10+1 -> 8 | B11: 202505 | C11: 45805 | D11: 大麦 | E11: 81202301710 | F11: 380 | G11: =H11/F11 -> 36619.65 | H11: 13915467 | I11: =FLOOR(H11,1000) -> 13915000 | J11: 1391400 | K11: 0 | L11: =ROUNDDOWN(I11*7.8/100,-2) -> 1085300 | M11: =J11-L11 -> 306100 | N11: 0 | O11: =ROUND(I11/F11*N11,-2) -> 0 | P11: =ROUNDDOWN(O11*7.8/100,-2) -> 0 | Q11: =R11-P11 -> 0 | R11: 0
A12: =A11+1 -> 9 | B12: 202505 | C12: 45805 | D12: 大麦 | E12: 81202301820 | F12: 380 | G12: =H12/F12 -> 36619.65 | H12: 13915467 | I12: =FLOOR(H12,1000) -> 13915000 | J12: 1391400 | K12: 0 | L12: =ROUNDDOWN(I12*7.8/100,-2) -> 1085300 | M12: =J12-L12 -> 306100 | N12: 0 | O12: =ROUND(I12/F12*N12,-2) -> 0 | P12: =ROUNDDOWN(O12*7.8/100,-2) -> 0 | Q12: =R12-P12 -> 0 | R12: 0
A13: =A12+1 -> 10 | B13: 202505 | C13: 45805 | D13: メイズ | E13: 81202307860 | F13: 500 | G13: =H13/F13 -> 38460.512 | H13: 19230256 | I13: =FLOOR(H13,1000) -> 19230000 | J13: 1922900 | K13: 0 | L13: =ROUNDDOWN(I13*7.8/100,-2) -> 1499900 | M13: =J13-L13 -> 423000 | N13: 0 | O13: =ROUND(I13/F13*N13,-2) -> 0 | P13: =ROUNDDOWN(O13*7.8/100,-2) -> 0 | Q13: =R13-P13 -> 0 | R13: 0
A14: =A13+1 -> 11 | B14: 202506 | C14: 45817 | D14: 大麦 | E14: 81202568520 | F14: 311.73 | G14: =H14/F14 -> 37731.919 | H14: 11762171 | I14: =FLOOR(H14,1000) -> 11762000 | J14: 1176100 | K14: 0 | L14: =ROUNDDOWN(I14*7.8/100,-2) -> 917400 | M14: =J14-L14 -> 258700 | N14: 311.73 | O14: =ROUND(I14/F14*N14,-2) -> 11762000 | P14: =ROUNDDOWN(O14*7.8/100,-2) -> 917400 | Q14: =R14-P14 -> 258700 | R14: 1176100
A15: =A14+1 -> 12 | B15: 202506 | C15: 45820 | D15: メイズ | E15: 81202639000 | F15: 1030 | G15: =H15/F15 -> 37587.959 | H15: 38715598 | I15: =FLOOR(H15,1000) -> 38715000 | J15: 3871400 | K15: 0 | L15: =ROUNDDOWN(I15*7.8/100,-2) -> 3019700 | M15: =J15-L15 -> 851700 | N15: 480 | O15: =ROUND(I15/F15*N15,-2) -> 18041900 | P15: =ROUNDDOWN(O15*7.8/100,-2) -> 1407200 | Q15: =R15-P15 -> 397000 | R15: 1804200
A16: =A15+1 -> 13 | B16: 202506 | C16: 45834 | D16: メイズ | E16: 81202932150 | F16: 960 | G16: =H16/F16 -> 36803.842 | H16: 35331688 | I16: =FLOOR(H16,1000) -> 35331000 | J16: 3533000 | K16: 0 | L16: =ROUNDDOWN(I16*7.8/100,-2) -> 2755800 | M16: =J16-L16 -> 777200 | N16: 400 | O16: =ROUND(I16/F16*N16,-2) -> 14721300 | P16: =ROUNDDOWN(O16*7.8/100,-2) -> 1148200 | Q16: =R16-P16 -> 323900 | R16: 1472100
... A24: =A23+1 -> 21 | B24: 202508 | C24: 45888 | D24: メイズ | E24: 81203863040 | F24: 2080 | G24: =H24/F24 -> 34508.018 | H24: 71776677 | I24: =FLOOR(H24,1000) -> 71776000 | J24: 7177500 | K24: 0 | L24: =ROUNDDOWN(I24*7.8/100,-2) -> 5598500 | M24: =J24-L24 -> 1579000 | N24: 880 | O24: =ROUND(I24/F24*N24,-2) -> 30366800 | P24: =ROUNDDOWN(O24*7.8/100,-2) -> 2368600 | Q24: =R24-P24 -> 668000 | R24: 3036600
A25: =A24+1 -> 22 | G25: =H25/F25 -> #DIV/0! | I25: =FLOOR(H25,1000) -> 0 | L25: =ROUNDDOWN(I25*7.8/100,-2) -> 0 | M25: =J25-L25 -> 0 | O25: =ROUND(I25/F25*N25,-2) -> #DIV/0! | P25: =ROUNDDOWN(O25*7.8/100,-2) -> #DIV/0! | Q25: =R25-P25 -> #DIV/0!
A26: =A25+1 -> 23 | G26: =H26/F26 -> #DIV/0! | I26: =FLOOR(H26,1000) -> 0 | L26: =ROUNDDOWN(I26*7.8/100,-2) -> 0 | M26: =J26-L26 -> 0 | O26: =ROUND(I26/F26*N26,-2) -> #DIV/0! | P26: =ROUNDDOWN(O26*7.8/100,-2) -> #DIV/0! | Q26: =R26-P26 -> #DIV/0!
A27: =A26+1 -> 24 | G27: =H27/F27 -> #DIV/0! | I27: =FLOOR(H27,1000) -> 0 | L27: =ROUNDDOWN(I27*7.8/100,-2) -> 0 | M27: =J27-L27 -> 0 | O27: =ROUND(I27/F27*N27,-2) -> #DIV/0! | P27: =ROUNDDOWN(O27*7.8/100,-2) -> #DIV/0! | Q27: =R27-P27 -> #DIV/0!
A28: =A27+1 -> 25 | G28: =H28/F28 -> #DIV/0! | I28: =FLOOR(H28,1000) -> 0 | L28: =ROUNDDOWN(I28*7.8/100,-2) -> 0 | M28: =J28-L28 -> 0 | O28: =ROUND(I28/F28*N28,-2) -> #DIV/0! | P28: =ROUNDDOWN(O28*7.8/100,-2) -> #DIV/0! | Q28: =R28-P28 -> #DIV/0!
A29: =A28+1 -> 26 | G29: =H29/F29 -> #DIV/0! | I29: =FLOOR(H29,1000) -> 0 | L29: =ROUNDDOWN(I29*7.8/100,-2) -> 0 | M29: =J29-L29 -> 0 | O29: =ROUND(I29/F29*N29,-2) -> #DIV/0! | P29: =ROUNDDOWN(O29*7.8/100,-2) -> #DIV/0! | Q29: =R29-P29 -> #DIV/0!
A30: =A29+1 -> 27 | G30: =H30/F30 -> #DIV/0! | I30: =FLOOR(H30,1000) -> 0 | L30: =ROUNDDOWN(I30*7.8/100,-2) -> 0 | M30: =J30-L30 -> 0 | O30: =ROUND(I30/F30*N30,-2) -> #DIV/0! | P30: =ROUNDDOWN(O30*7.8/100,-2) -> #DIV/0! | Q30: =R30-P30 -> #DIV/0!
A31: =A30+1 -> 28 | G31: =H31/F31 -> #DIV/0! | I31: =FLOOR(H31,1000) -> 0 | L31: =ROUNDDOWN(I31*7.8/100,-2) -> 0 | M31: =J31-L31 -> 0 | O31: =ROUND(I31/F31*N31,-2) -> #DIV/0! | P31: =ROUNDDOWN(O31*7.8/100,-2) -> #DIV/0! | Q31: =R31-P31 -> #DIV/0!
A32: =A31+1 -> 29 | G32: =H32/F32 -> #DIV/0! | I32: =FLOOR(H32,1000) -> 0 | L32: =ROUNDDOWN(I32*7.8/100,-2) -> 0 | M32: =J32-L32 -> 0 | O32: =ROUND(I32/F32*N32,-2) -> #DIV/0! | P32: =ROUNDDOWN(O32*7.8/100,-2) -> #DIV/0! | Q32: =R32-P32 -> #DIV/0!
A33: =A32+1 -> 30 | G33: =H33/F33 -> #DIV/0! | I33: =FLOOR(H33,1000) -> 0 | L33: =ROUNDDOWN(I33*7.8/100,-2) -> 0 | M33: =J33-L33 -> 0 | O33: =ROUND(I33/F33*N33,-2) -> #DIV/0! | P33: =ROUNDDOWN(O33*7.8/100,-2) -> #DIV/0! | Q33: =R33-P33 -> #DIV/0!
A34: =A33+1 -> 31 | G34: =H34/F34 -> #DIV/0! | I34: =FLOOR(H34,1000) -> 0 | L34: =ROUNDDOWN(I34*7.8/100,-2) -> 0 | M34: =J34-L34 -> 0 | O34: =ROUND(I34/F34*N34,-2) -> #DIV/0! | P34: =ROUNDDOWN(O34*7.8/100,-2) -> #DIV/0! | Q34: =R34-P34 -> #DIV/0!
A35: =A34+1 -> 32 | G35: =H35/F35 -> #DIV/0! | I35: =FLOOR(H35,1000) -> 0 | L35: =ROUNDDOWN(I35*7.8/100,-2) -> 0 | M35: =J35-L35 -> 0 | O35: =ROUND(I35/F35*N35,-2) -> #DIV/0! | P35: =ROUNDDOWN(O35*7.8/100,-2) -> #DIV/0! | Q35: =R35-P35 -> #DIV/0!
A36: =A35+1 -> 33 | G36: =H36/F36 -> #DIV/0! | I36: =FLOOR(H36,1000) -> 0 | L36: =ROUNDDOWN(I36*7.8/100,-2) -> 0 | M36: =J36-L36 -> 0 | O36: =ROUND(I36/F36*N36,-2) -> #DIV/0! | P36: =ROUNDDOWN(O36*7.8/100,-2) -> #DIV/0! | Q36: =R36-P36 -> #DIV/0!
... A51: =A50+1 -> 48 | G51: =H51/F51 -> #DIV/0! | I51: =FLOOR(H51,1000) -> 0 | L51: =ROUNDDOWN(I51*7.8/100,-2) -> 0 | M51: =J51-L51 -> 0 | O51: =ROUND(I51/F51*N51,-2) -> #DIV/0! | P51: =ROUNDDOWN(O51*7.8/100,-2) -> #DIV/0! | Q51: =R51-P51 -> #DIV/0!
P52: =SUM(P4:P51) -> #DIV/0! | Q52: =SUM(Q4:Q51) -> #DIV/0! | R52: =SUM(R4:R51) -> 19793900

Sheet 消費税負担分2024
A3: 対象年月 | B3: 通関年月日 | C3: 原料名 | D3: 通関NO | E3: 全体数量 （MT） | F3: 単価/ｔ | G3: 申告価格 | H3: 消費税計算用 （100円以下切捨て） | I3: 消費税額 | J3: D関税 | K3: F消費税 （7.8％） | L3: A地方消費税 （22/78） | M3: B負担分 数量 （MT） | N3: 負担分の 申告価格 割り返し | O3: ①消費税 （7.8％） | P3: ②地方消費税 （22/78） | Q3: 消費税 負担額
A4: 202404 | B4: 45385 | C4: 大麦 | D4: 81194773210 | E4: 630 | F4: =G4/E4 -> 42848.127 | G4: 26994320 | H4: 26994000 | I4: 2699300 | J4: 0 | K4: =ROUNDDOWN(H4*7.8/100,-2) -> 2105500 | L4: =I4-K4 -> 593800 | M4: 0 | N4: =ROUND(H4/E4*M4,-2) -> 0 | O4: =ROUNDDOWN(N4*7.8/100,-2) -> 0 | P4: =Q4-O4 -> 0 | Q4: 0
A5: 202404 | B5: 45398 | C5: メイズ | D5: 81195019830 | E5: 1420 | F5: =G5/E5 -> 36042.111 | G5: 51179797 | H5: 51179000 | I5: 5117800 | J5: 0 | K5: =ROUNDDOWN(H5*7.8/100,-2) -> 3991900 | L5: =I5-K5 -> 1125900 | M5: 720 | N5: =ROUND(H5/E5*M5,-2) -> 25949900 | O5: =ROUNDDOWN(N5*7.8/100,-2) -> 2024000 | P5: =Q5-O5 -> 571000 | Q5: 2595000
A6: 202404 | B6: 45399 | C6: 大麦 | D6: 81195052400 | E6: 325.5 | F6: =G6/E6 -> 41500.006 | G6: 13508252 | H6: 13508000 | I6: 1350700 | J6: 0 | K6: =ROUNDDOWN(H6*7.8/100,-2) -> 1053600 | L6: =I6-K6 -> 297100 | M6: 325.5 | N6: =ROUND(H6/E6*M6,-2) -> 13508000 | O6: =ROUNDDOWN(N6*7.8/100,-2) -> 1053600 | P6: =Q6-O6 -> 297100 | Q6: 1350700
A7: 202405 | B7: 45414 | C7: メイズ | D7: 81195303000 | E7: 1480 | F7: =G7/E7 -> 36615.784 | G7: 54191361 | H7: 54191000 | I7: 5418900 | J7: 0 | K7: =ROUNDDOWN(H7*7.8/100,-2) -> 4226800 | L7: =I7-K7 -> 1192100 | M7: 380 | N7: =ROUND(H7/E7*M7,-2) -> 13913900 | O7: =ROUNDDOWN(N7*7.8/100,-2) -> 1085200 | P7: =Q7-O7 -> 306100 | Q7: 1391300
A8: 202405 | B8: 45425 | C8: 大麦 | D8: 81195475640 | E8: 135.76 | F8: =G8/E8 -> 43778.263 | G8: 5943337 | H8: 5943000 | I8: 594200 | J8: 0 | K8: =ROUNDDOWN(H8*7.8/100,-2) -> 463500 | L8: =I8-K8 -> 130700 | M8: 0 | N8: =ROUND(H8/E8*M8,-2) -> 0 | O8: =ROUNDDOWN(N8*7.8/100,-2) -> 0 | P8: =Q8-O8 -> 0 | Q8: 0
A9: 202405 | B9: 45429 | C9: メイズ | D9: 81195629420 | E9: 1800 | F9: =G9/E9 -> 39891.957 | G9: 71805522 | H9: 71805000 | I9: 7180300 | J9: 0 | K9: =ROUNDDOWN(H9*7.8/100,-2) -> 5600700 | L9: =I9-K9 -> 1579600 | M9: 800 | N9: =ROUND(H9/E9*M9,-2) -> 31913300 | O9: =ROUNDDOWN(N9*7.8/100,-2) -> 2489200 | P9: =Q9-O9 -> 702100 | Q9: 3191300
A10: 202405 | B10: 45433 | C10: 大麦 | D10: 81195674550 | E10: 450.2 | F10: =G10/E10 -> 43191.906 | G10: 19444996 | H10: 19444000 | I10: 1944300 | J10: 0 | K10: =ROUNDDOWN(H10*7.8/100,-2) -> 1516600 | L10: =I10-K10 -> 427700 | M10: 0 | N10: =ROUND(H10/E10*M10,-2) -> 0 | O10: =ROUNDDOWN(N10*7.8/100,-2) -> 0 | P10: =Q10-O10 -> 0 | Q10: 0
A11: 202405 | B11: 45435 | C11: 大麦 | D11: 81195746100 | E11: 200.01 | F11: =G11/E11 -> 43191.905 | G11: 8638813 | H11: 8638000 | I11: 863700 | J11: 0 | K11: =ROUNDDOWN(H11*7.8/100,-2) -> 673700 | L11: =I11-K11 -> 190000 | M11: 0 | N11: =ROUND(H11/E11*M11,-2) -> 0 | O11: =ROUNDDOWN(N11*7.8/100,-2) -> 0 | P11: =Q11-O11 -> 0 | Q11: 0
A12: 202406 | B12: 45454 | C12: 大麦 | D12: 81196092560 | E12: 599.8 | F12: =G12/E12 -> 43008.006 | G12: 25796202 | H12: 25796000 | I12: 2579400 | J12: 0 | K12: =ROUNDDOWN(H12*7.8/100,-2) -> 2012000 | L12: =I12-K12 -> 567400 | M12: 0 | N12: =ROUND(H12/E12*M12,-2) -> 0 | O12: =ROUNDDOWN(N12*7.8/100,-2) -> 0 | P12: =Q12-O12 -> 0 | Q12: 0
A13: 202406 | B13: 45454 | C13: 大麦 | D13: 81196092600 | E13: 1088.23 | F13: =G13/E13 -> 43008.007 | G13: 46802603 | H13: 46802000 | I13: 4680100 | J13: 0 | K13: =ROUNDDOWN(H13*7.8/100,-2) -> 3650500 | L13: =I13-K13 -> 1029600 | M13: 0 | N13: =ROUND(H13/E13*M13,-2) -> 0 | O13: =ROUNDDOWN(N13*7.8/100,-2) -> 0 | P13: =Q13-O13 -> 0 | Q13: 0
A14: 202406 | B14: 45455 | C14: メイズ | D14: 81196119900 | E14: 2150 | F14: =G14/E14 -> 39243.916 | G14: 84374420 | H14: 84374000 | I14: 8437300 | J14: 0 | K14: =ROUNDDOWN(H14*7.8/100,-2) -> 6581100 | L14: =I14-K14 -> 1856200 | M14: 1000 | N14: =ROUND(H14/E14*M14,-2) -> 39243700 | O14: =ROUNDDOWN(N14*7.8/100,-2) -> 3061000 | P14: =Q14-O14 -> 863300 | Q14: 3924300
A15: 202406 | B15: 45464 | C15: 大麦 | D15: 81196290220 | E15: 315 | F15: =G15/E15 -> 43615.441 | G15: 13738864 | H15: 13738000 | I15: 1373700 | J15: 0 | K15: =ROUNDDOWN(H15*7.8/100,-2) -> 1071500 | L15: =I15-K15 -> 302200 | M15: 315 | N15: =ROUND(H15/E15*M15,-2) -> 13738000 | O15: =ROUNDDOWN(N15*7.8/100,-2) -> 1071500 | P15: =Q15-O15 -> 302200 | Q15: 1373700
... A36: 202502 | B36: 45698 | C36: 大麦 | D36: 81200361860 | E36: 577.5 | F36: =G36/E36 -> 40629.721 | G36: 23463664 | H36: 23463000 | I36: 2346200 | J36: 0 | K36: =ROUNDDOWN(H36*7.8/100,-2) -> 1830100 | L36: =I36-K36 -> 516100 | M36: 0 | N36: =ROUND(H36/E36*M36,-2) -> 0 | O36: =ROUNDDOWN(N36*7.8/100,-2) -> 0 | P36: =Q36-O36 -> 0 | Q36: 0
A37: 202502 | B37: 45708 | C37: 大麦 | D37: 81200593450 | E37: 189 | F37: =G37/E37 -> 39052.492 | G37: 7380921 | H37: 7380000 | I37: 737900 | J37: 0 | K37: =ROUNDDOWN(H37*7.8/100,-2) -> 575600 | L37: =I37-K37 -> 162300 | M37: 189 | N37: =ROUND(H37/E37*M37,-2) -> 7380000 | O37: =ROUNDDOWN(N37*7.8/100,-2) -> 575600 | P37: =Q37-O37 -> 162300 | Q37: 737900 | R37: ＊1
A38: 202502 | B38: 45713 | C38: メイズ | D38: 81200652950 | E38: 1230 | F38: =G38/E38 -> 38815.463 | G38: 47743019 | H38: 47743000 | I38: 4774200 | J38: 0 | K38: =ROUNDDOWN(H38*7.8/100,-2) -> 3723900 | L38: =I38-K38 -> 1050300 | M38: 730 | N38: =ROUND(H38/E38*M38,-2) -> 28335300 | O38: =ROUNDDOWN(N38*7.8/100,-2) -> 2210100 | P38: =Q38-O38 -> 623300 | Q38: 2833400
A39: 202502 | B39: 45716 | C39: 大麦 | D39: 81200702800 | E39: 357 | F39: =G39/E39 -> 40108.289 | G39: 14318659 | H39: 14318000 | I39: 1431700 | J39: 0 | K39: =ROUNDDOWN(H39*7.8/100,-2) -> 1116800 | L39: =I39-K39 -> 314900 | M39: 0 | N39: =ROUND(H39/E39*M39,-2) -> 0 | O39: =ROUNDDOWN(N39*7.8/100,-2) -> 0 | P39: =Q39-O39 -> 0 | Q39: 0
A40: 202503 | B40: 45721 | C40: 大麦 | D40: 81200779210 | E40: 231 | F40: =G40/E40 -> 39869.268 | G40: 9209801 | H40: 9209000 | I40: 920800 | J40: 0 | K40: =ROUNDDOWN(H40*7.8/100,-2) -> 718300 | L40: =I40-K40 -> 202500 | M40: 0 | N40: =ROUND(H40/E40*M40,-2) -> 0 | O40: =ROUNDDOWN(N40*7.8/100,-2) -> 0 | P40: =Q40-O40 -> 0 | Q40: 0
A41: 202503 | B41: 45726 | C41: 大麦 | D41: 81200869730 | E41: 367.5 | F41: =G41/E41 -> 39387.018 | G41: 14474729 | H41: 14474000 | I41: 1447300 | J41: 0 | K41: =ROUNDDOWN(H41*7.8/100,-2) -> 1128900 | L41: =I41-K41 -> 318400 | M41: 0 | N41: =ROUND(H41/E41*M41,-2) -> 0 | O41: =ROUNDDOWN(N41*7.8/100,-2) -> 0 | P41: =Q41-O41 -> 0 | Q41: 0
A42: 202503 | B42: 45735 | C42: メイズ | D42: 81201044730 | E42: 1825 | F42: =G42/E42 -> 41276.687 | G42: 75329953 | H42: 75329000 | I42: 7532800 | J42: 0 | K42: =ROUNDDOWN(H42*7.8/100,-2) -> 5875600 | L42: =I42-K42 -> 1657200 | M42: 850 | N42: =ROUND(H42/E42*M42,-2) -> 35084700 | O42: =ROUNDDOWN(N42*7.8/100,-2) -> 2736600 | P42: =Q42-O42 -> 771800 | Q42: 3508400
A43: 202503 | B43: 45735 | C43: 大麦 | D43: 81200593450 | E43: 189 | F43: =G43/E43 -> 39244.677 | G43: =7417244 -> 7417244 | H43: =7417000 -> 7417000 | I43: 3700 | J43: 0 | K43: =ROUNDDOWN(H43*7.8/100,-2)-K37 -> 2900 | L43: =I43-K43 -> 800 | M43: 189 | N43: =ROUND(H43/E43*M43,-2) -> 7417000 | O43: =ROUNDDOWN(N43*7.8/100,-2)-O37 -> 2900 | P43: =Q43-O43 -> 800 | Q43: 3700 | R43: ＊1の修正申告
A44: 202503 | B44: 45741 | C44: 大麦 | D44: 81201120920 | E44: 399 | F44: =G44/E44 -> 38161.018 | G44: 15226246 | H44: 15226000 | I44: 1522500 | J44: 0 | K44: =ROUNDDOWN(H44*7.8/100,-2) -> 1187600 | L44: =I44-K44 -> 334900 | M44: 0 | N44: =ROUND(H44/E44*M44,-2) -> 0 | O44: =ROUNDDOWN(N44*7.8/100,-2) -> 0 | P44: =Q44-O44 -> 0 | Q44: 0
A45: 202503 | B45: 45742 | C45: 大麦 | D45: 81201165020 | E45: 120 | F45: =G45/E45 -> 37707.075 | G45: 4524849 | H45: 4524000 | I45: 452300 | J45: 0 | K45: =ROUNDDOWN(H45*7.8/100,-2) -> 352800 | L45: =I45-K45 -> 99500 | M45: 120 | N45: =ROUND(H45/E45*M45,-2) -> 4524000 | O45: =ROUNDDOWN(N45*7.8/100,-2) -> 352800 | P45: =Q45-O45 -> 99500 | Q45: 452300
F46: =G46/E46 -> #DIV/0! | K46: =ROUNDDOWN(H46*7.8/100,-2) -> 0 | L46: =I46-K46 -> 0 | N46: =ROUND(H46/E46*M46,-2) -> #DIV/0! | O46: =ROUNDDOWN(N46*7.8/100,-2) -> #DIV/0! | P46: =Q46-O46 -> #DIV/0!
F47: =G47/E47 -> #DIV/0! | K47: =ROUNDDOWN(H47*7.8/100,-2) -> 0 | L47: =I47-K47 -> 0 | N47: =ROUND(H47/E47*M47,-2) -> #DIV/0! | O47: =ROUNDDOWN(N47*7.8/100,-2) -> #DIV/0! | P47: =Q47-O47 -> #DIV/0!
F48: =G48/E48 -> #DIV/0! | K48: =ROUNDDOWN(H48*7.8/100,-2) -> 0 | L48: =I48-K48 -> 0 | N48: =ROUND(H48/E48*M48,-2) -> #DIV/0! | O48: =ROUNDDOWN(N48*7.8/100,-2) -> #DIV/0! | P48: =Q48-O48 -> #DIV/0!
F49: =G49/E49 -> #DIV/0! | K49: =ROUNDDOWN(H49*7.8/100,-2) -> 0 | L49: =I49-K49 -> 0 | N49: =ROUND(H49/E49*M49,-2) -> #DIV/0! | O49: =ROUNDDOWN(N49*7.8/100,-2) -> #DIV/0! | P49: =Q49-O49 -> #DIV/0!
F50: =G50/E50 -> #DIV/0! | K50: =ROUNDDOWN(H50*7.8/100,-2) -> 0 | L50: =I50-K50 -> 0 | N50: =ROUND(H50/E50*M50,-2) -> #DIV/0! | O50: =ROUNDDOWN(N50*7.8/100,-2) -> #DIV/0! | P50: =Q50-O50 -> #DIV/0!
F51: =G51/E51 -> #DIV/0! | K51: =ROUNDDOWN(H51*7.8/100,-2) -> 0 | L51: =I51-K51 -> 0 | N51: =ROUND(H51/E51*M51,-2) -> #DIV/0! | O51: =ROUNDDOWN(N51*7.8/100,-2) -> #DIV/0! | P51: =Q51-O51 -> #DIV/0!
O52: =SUM(O4:O51) -> #DIV/0! | P52: =SUM(P4:P51) -> #DIV/0! | Q52: =SUM(Q4:Q51) -> 47960400

Sheet 消費税負担分2023
A3: 対象年月 | B3: 通関年月日 | C3: 原料名 | D3: 通関NO | E3: 全体数量 （MT） | F3: 単価/ｔ | G3: 申告価格 | H3: 消費税計算用 （100円以下切捨て） | I3: 消費税額 | J3: D関税 | K3: F消費税 （7.8％） | L3: A地方消費税 （22/78） | M3: B負担分 数量 （MT） | N3: 負担分の 申告価格 割り返し | O3: ①消費税 （7.8％） | P3: ②地方消費税 （22/78） | Q3: 消費税 負担額
A4: 202304 | B4: 45034 | C4: メイズ | D4: 81188665230 | E4: 530 | F4: =G4/E4 -> 46998.445 | G4: 24909176 | H4: 24909000 | I4: 2490800 | J4: 0 | K4: =ROUNDDOWN(H4*7.8/100,-2) -> 1942900 | L4: =I4-K4 -> 547900 | M4: 180 | N4: =ROUND(H4/E4*M4,-2) -> 8459700 | O4: =ROUNDDOWN(N4*7.8/100,-2) -> 659800 | P4: =Q4-O4 -> 186100 | Q4: 845900
A5: 202304 | B5: 45034 | C5: メイズ | D5: 81188665340 | E5: 1620 | F5: =G5/E5 -> 44579.077 | G5: 72218105 | H5: 72218000 | I5: 7221700 | J5: 0 | K5: =ROUNDDOWN(H5*7.8/100,-2) -> 5633000 | L5: =I5-K5 -> 1588700 | M5: 570 | N5: =ROUND(H5/E5*M5,-2) -> 25410000 | O5: =ROUNDDOWN(N5*7.8/100,-2) -> 1981900 | P5: =Q5-O5 -> 559100 | Q5: 2541000
A6: 202304 | B6: 45036 | C6: 大麦 | D6: 81188736850 | E6: 577.5 | F6: =G6/E6 -> 43010.253 | G6: 24838421 | H6: 24838000 | I6: 2483700 | J6: 0 | K6: =ROUNDDOWN(H6*7.8/100,-2) -> 1937300 | L6: =I6-K6 -> 546400 | M6: 0 | N6: =ROUND(H6/E6*M6,-2) -> 0 | O6: =ROUNDDOWN(N6*7.8/100,-2) -> 0 | P6: =Q6-O6 -> 0 | Q6: 0
A7: 202304 | B7: 45043 | C7: メイズ | D7: 81188879650 | E7: 150 | F7: =G7/E7 -> 48262.933 | G7: 7239440 | H7: 7239000 | I7: 723800 | J7: 0 | K7: =ROUNDDOWN(H7*7.8/100,-2) -> 564600 | L7: =I7-K7 -> 159200 | M7: 150 | N7: =ROUND(H7/E7*M7,-2) -> 7239000 | O7: =ROUNDDOWN(N7*7.8/100,-2) -> 564600 | P7: =Q7-O7 -> 159200 | Q7: 723800
A8: 202305 | B8: 45064 | C8: メイズ | D8: 81189244130 | E8: 1780 | F8: =G8/E8 -> 47661.072 | G8: 84836709 | H8: 84836000 | I8: 8483500 | J8: 0 | K8: =ROUNDDOWN(H8*7.8/100,-2) -> 6617200 | L8: =I8-K8 -> 1866300 | M8: 880 | N8: =ROUND(H8/E8*M8,-2) -> 41941400 | O8: =ROUNDDOWN(N8*7.8/100,-2) -> 3271400 | P8: =Q8-O8 -> 922700 | Q8: 4194100
A9: 202305 | B9: 45072 | C9: 大麦 | D9: 81189425100 | E9: 50 | F9: =G9/E9 -> 42484.06 | G9: 2124203 | H9: 2124000 | I9: 212300 | J9: 0 | K9: =ROUNDDOWN(H9*7.8/100,-2) -> 165600 | L9: =I9-K9 -> 46700 | M9: 50 | N9: =ROUND(H9/E9*M9,-2) -> 2124000 | O9: =ROUNDDOWN(N9*7.8/100,-2) -> 165600 | P9: =Q9-O9 -> 46700 | Q9: 212300
A10: 202306 | B10: 45079 | C10: メイズ | D10: 81189536140 | E10: 400 | F10: =G10/E10 -> 48023.827 | G10: 19209531 | H10: 19209000 | I10: 1920800 | J10: 0 | K10: =ROUNDDOWN(H10*7.8/100,-2) -> 1498300 | L10: =I10-K10 -> 422500 | M10: 0 | N10: =ROUND(H10/E10*M10,-2) -> 0 | O10: =ROUNDDOWN(N10*7.8/100,-2) -> 0 | P10: =Q10-O10 -> 0 | Q10: 0
A11: 202306 | B11: 45083 | C11: 大麦 | D11: 81189600430 | E11: 420 | F11: =G11/E11 -> 42412.388 | G11: 17813203 | H11: 17813000 | I11: 1781200 | J11: 0 | K11: =ROUNDDOWN(H11*7.8/100,-2) -> 1389400 | L11: =I11-K11 -> 391800 | M11: 420 | N11: =ROUND(H11/E11*M11,-2) -> 17813000 | O11: =ROUNDDOWN(N11*7.8/100,-2) -> 1389400 | P11: =Q11-O11 -> 391800 | Q11: 1781200
A12: 202306 | B12: 45084 | C12: メイズ | D12: 81189624450 | E12: 1500 | F12: =G12/E12 -> 48708.206 | G12: 73062309 | H12: 73062000 | I12: 7306100 | J12: 0 | K12: =ROUNDDOWN(H12*7.8/100,-2) -> 5698800 | L12: =I12-K12 -> 1607300 | M12: 1000 | N12: =ROUND(H12/E12*M12,-2) -> 48708000 | O12: =ROUNDDOWN(N12*7.8/100,-2) -> 3799200 | P12: =Q12-O12 -> 1071500 | Q12: 4870700
A13: 202306 | B13: 45084 | C13: 大麦 | D13: 81189635320 | E13: 600 | F13: =G13/E13 -> 43732.807 | G13: 26239684 | H13: 26239000 | I13: 2623800 | J13: 0 | K13: =ROUNDDOWN(H13*7.8/100,-2) -> 2046600 | L13: =I13-K13 -> 577200 | M13: 0 | N13: =ROUND(H13/E13*M13,-2) -> 0 | O13: =ROUNDDOWN(N13*7.8/100,-2) -> 0 | P13: =Q13-O13 -> 0 | Q13: 0
A14: 202306 | B14: 45084 | C14: 大麦 | D14: 81189633700 | E14: 1150.43 | F14: =G14/E14 -> 42565.307 | G14: 48968406 | H14: 48968000 | I14: 4896700 | J14: 0 | K14: =ROUNDDOWN(H14*7.8/100,-2) -> 3819500 | L14: =I14-K14 -> 1077200 | M14: 0 | N14: =ROUND(H14/E14*M14,-2) -> 0 | O14: =ROUNDDOWN(N14*7.8/100,-2) -> 0 | P14: =Q14-O14 -> 0 | Q14: 0
A15: 202306 | B15: 45084 | C15: 大麦 | D15: 81189633810 | E15: 450 | F15: =G15/E15 -> 42412.389 | G15: 19085575 | H15: 19085000 | I15: 1908400 | J15: 0 | K15: =ROUNDDOWN(H15*7.8/100,-2) -> 1488600 | L15: =I15-K15 -> 419800 | M15: 0 | N15: =ROUND(H15/E15*M15,-2) -> 0 | O15: =ROUNDDOWN(N15*7.8/100,-2) -> 0 | P15: =Q15-O15 -> 0 | Q15: 0
... A44: 202403 | B44: 45377 | C44: 大麦 | D44: 81194583620 | E44: 400 | F44: =G44/E44 -> 40796.005 | G44: 16318402 | H44: 16318000 | I44: 1631700 | J44: 0 | K44: =ROUNDDOWN(H44*7.8/100,-2) -> 1272800 | L44: =I44-K44 -> 358900 | M44: 0 | N44: =ROUND(H44/E44*M44,-2) -> 0 | O44: =ROUNDDOWN(N44*7.8/100,-2) -> 0 | P44: =Q44-O44 -> 0 | Q44: 0
F45: =G45/E45 -> #DIV/0! | K45: =ROUNDDOWN(H45*7.8/100,-2) -> 0 | L45: =I45-K45 -> 0 | N45: =ROUND(H45/E45*M45,-2) -> #DIV/0! | O45: =ROUNDDOWN(N45*7.8/100,-2) -> #DIV/0! | P45: =Q45-O45 -> #DIV/0!
F46: =G46/E46 -> #DIV/0! | K46: =ROUNDDOWN(H46*7.8/100,-2) -> 0 | L46: =I46-K46 -> 0 | N46: =ROUND(H46/E46*M46,-2) -> #DIV/0! | O46: =ROUNDDOWN(N46*7.8/100,-2) -> #DIV/0! | P46: =Q46-O46 -> #DIV/0!
F47: =G47/E47 -> #DIV/0! | K47: =ROUNDDOWN(H47*7.8/100,-2) -> 0 | L47: =I47-K47 -> 0 | N47: =ROUND(H47/E47*M47,-2) -> #DIV/0! | O47: =ROUNDDOWN(N47*7.8/100,-2) -> #DIV/0! | P47: =Q47-O47 -> #DIV/0!
F48: =G48/E48 -> #DIV/0! | K48: =ROUNDDOWN(H48*7.8/100,-2) -> 0 | L48: =I48-K48 -> 0 | N48: =ROUND(H48/E48*M48,-2) -> #DIV/0! | O48: =ROUNDDOWN(N48*7.8/100,-2) -> #DIV/0! | P48: =Q48-O48 -> #DIV/0!
F49: =G49/E49 -> #DIV/0! | K49: =ROUNDDOWN(H49*7.8/100,-2) -> 0 | L49: =I49-K49 -> 0 | N49: =ROUND(H49/E49*M49,-2) -> #DIV/0! | O49: =ROUNDDOWN(N49*7.8/100,-2) -> #DIV/0! | P49: =Q49-O49 -> #DIV/0!
F50: =G50/E50 -> #DIV/0! | K50: =ROUNDDOWN(H50*7.8/100,-2) -> 0 | L50: =I50-K50 -> 0 | N50: =ROUND(H50/E50*M50,-2) -> #DIV/0! | O50: =ROUNDDOWN(N50*7.8/100,-2) -> #DIV/0! | P50: =Q50-O50 -> #DIV/0!
F51: =G51/E51 -> #DIV/0! | K51: =ROUNDDOWN(H51*7.8/100,-2) -> 0 | L51: =I51-K51 -> 0 | N51: =ROUND(H51/E51*M51,-2) -> #DIV/0! | O51: =ROUNDDOWN(N51*7.8/100,-2) -> #DIV/0! | P51: =Q51-O51 -> #DIV/0!
O52: =SUM(O4:O51) -> #DIV/0! | P52: =SUM(P4:P51) -> #DIV/0! | Q52: =SUM(Q4:Q51) -> 52130800

Sheet 消費税負担分2022
A3: 対象年月 | B3: 通関年月日 | C3: 原料名 | D3: 通関NO | E3: 全体数量 （MT） | F3: 単価/ｔ | G3: 申告価格 | H3: 消費税計算用 （100円以下切捨て） | I3: 消費税額 | J3: D関税 | K3: F消費税 （7.8％） | L3: A地方消費税 （22/78） | M3: B負担分 数量 （MT） | N3: 負担分の 申告価格 割り返し | O3: ①消費税 （7.8％） | P3: ②地方消費税 （22/78） | Q3: 消費税 負担額
A4: 202204 | B4: 44652 | C4: 大麦 | D4: 81181311620 | E4: 400 | F4: =G4/E4 -> 39709.232 | G4: 15883693 | H4: 15883000 | I4: 1588200 | J4: 0 | K4: =ROUNDDOWN(H4*7.8/100,-2) -> 1238800 | L4: =I4-K4 -> 349400 | M4: 0 | N4: =ROUND(H4/E4*M4,-2) -> 0 | O4: =ROUNDDOWN(N4*7.8/100,-2) -> 0 | P4: =Q4-O4 -> 0 | Q4: 0
A5: 202204 | B5: 44656 | C5: 大麦 | D5: 81181360950 | E5: 250 | F5: =G5/E5 -> 38982.576 | G5: 9745644 | H5: 9745000 | I5: 974400 | J5: 0 | K5: =ROUNDDOWN(H5*7.8/100,-2) -> 760100 | L5: =I5-K5 -> 214300 | M5: 250 | N5: =ROUND(H5/E5*M5,-2) -> 9745000 | O5: =ROUNDDOWN(N5*7.8/100,-2) -> 760100 | P5: =Q5-O5 -> 214300 | Q5: 974400
A6: 202204 | B6: 44663 | C6: 大麦 | D6: 81181536210 | E6: 400 | F6: =G6/E6 -> 39508.44 | G6: 15803376 | H6: 15803000 | I6: 1580200 | J6: 0 | K6: =ROUNDDOWN(H6*7.8/100,-2) -> 1232600 | L6: =I6-K6 -> 347600 | M6: 0 | N6: =ROUND(H6/E6*M6,-2) -> 0 | O6: =ROUNDDOWN(N6*7.8/100,-2) -> 0 | P6: =Q6-O6 -> 0 | Q6: 0
A7: 202204 | B7: 44666 | C7: メイズ | D7: 81181652300 | E7: 750 | F7: =G7/E7 -> 44619.225 | G7: 33464419 | H7: 33464000 | I7: 3346200 | J7: 0 | K7: =ROUNDDOWN(H7*7.8/100,-2) -> 2610100 | L7: =I7-K7 -> 736100 | M7: 0 | N7: =ROUND(H7/E7*M7,-2) -> 0 | O7: =ROUNDDOWN(N7*7.8/100,-2) -> 0 | P7: =Q7-O7 -> 0 | Q7: 0
A8: 202204 | B8: 44672 | C8: メイズ | D8: 81181763120 | E8: 1220 | F8: =G8/E8 -> 44843.626 | G8: 54709224 | H8: 54709000 | I8: 5470800 | J8: 0 | K8: =ROUNDDOWN(H8*7.8/100,-2) -> 4267300 | L8: =I8-K8 -> 1203500 | M8: 820 | N8: =ROUND(H8/E8*M8,-2) -> 36771600 | O8: =ROUNDDOWN(N8*7.8/100,-2) -> 2868100 | P8: =Q8-O8 -> 809000 | Q8: 3677100
A9: 202205 | B9: 44690 | C9: メイズ | D9: 81182053360 | E9: 960 | F9: =G9/E9 -> 52011.955 | G9: 49931477 | H9: 49931000 | I9: 4993000 | J9: 0 | K9: =ROUNDDOWN(H9*7.8/100,-2) -> 3894600 | L9: =I9-K9 -> 1098400 | M9: 360 | N9: =ROUND(H9/E9*M9,-2) -> 18724100 | O9: =ROUNDDOWN(N9*7.8/100,-2) -> 1460400 | P9: =Q9-O9 -> 412000 | Q9: 1872400
A10: 202205 | B10: 44701 | C10: 大麦 | D10: 81182346000 | E10: 420 | F10: =G10/E10 -> 43708.002 | G10: 18357361 | H10: 18357000 | I10: 1835600 | J10: 0 | K10: =ROUNDDOWN(H10*7.8/100,-2) -> 1431800 | L10: =I10-K10 -> 403800 | M10: 0 | N10: =ROUND(H10/E10*M10,-2) -> 0 | O10: =ROUNDDOWN(N10*7.8/100,-2) -> 0 | P10: =Q10-O10 -> 0 | Q10: 0
A11: 202205 | B11: 44705 | C11: メイズ | D11: 81182414710 | E11: 2750 | F11: =G11/E11 -> 47957.417 | G11: 131882897 | H11: 131882000 | I11: 13188000 | J11: 0 | K11: =ROUNDDOWN(H11*7.8/100,-2) -> 10286700 | L11: =I11-K11 -> 2901300 | M11: 1250 | N11: =ROUND(H11/E11*M11,-2) -> 59946400 | O11: =ROUNDDOWN(N11*7.8/100,-2) -> 4675800 | P11: =Q11-O11 -> 1318800 | Q11: 5994600
A12: 202206 | B12: 44715 | C12: メイズ | D12: 81182643940 | E12: 600 | F12: =G12/E12 -> 55527.082 | G12: 33316249 | H12: 33316000 | I12: 3331500 | J12: 0 | K12: =ROUNDDOWN(H12*7.8/100,-2) -> 2598600 | L12: =I12-K12 -> 732900 | M12: 0 | N12: =ROUND(H12/E12*M12,-2) -> 0 | O12: =ROUNDDOWN(N12*7.8/100,-2) -> 0 | P12: =Q12-O12 -> 0 | Q12: 0
A13: 202206 | B13: 44719 | C13: 大麦 | D13: 81182717810 | E13: 367.5 | F13: =G13/E13 -> 42930.144 | G13: 15776828 | H13: 15776000 | I13: 1577500 | J13: 0 | K13: =ROUNDDOWN(H13*7.8/100,-2) -> 1230500 | L13: =I13-K13 -> 347000 | M13: 367.5 | N13: =ROUND(H13/E13*M13,-2) -> 15776000 | O13: =ROUNDDOWN(N13*7.8/100,-2) -> 1230500 | P13: =Q13-O13 -> 347000 | Q13: 1577500
A14: 202206 | B14: 44727 | C14: 大麦 | D14: 81182894060 | E14: 1045 | F14: =G14/E14 -> 40585.1 | G14: 42411430 | H14: 42411000 | I14: 4241000 | J14: 0 | K14: =ROUNDDOWN(H14*7.8/100,-2) -> 3308000 | L14: =I14-K14 -> 933000 | M14: 0 | N14: =ROUND(H14/E14*M14,-2) -> 0 | O14: =ROUNDDOWN(N14*7.8/100,-2) -> 0 | P14: =Q14-O14 -> 0 | Q14: 0
A15: 202206 | B15: 44729 | C15: メイズ | D15: 81182947410 | E15: 900 | F15: =G15/E15 -> 55548.538 | G15: 49993684 | H15: 49993000 | I15: 4999200 | J15: 0 | K15: =ROUNDDOWN(H15*7.8/100,-2) -> 3899400 | L15: =I15-K15 -> 1099800 | M15: 800 | N15: =ROUND(H15/E15*M15,-2) -> 44438200 | O15: =ROUNDDOWN(N15*7.8/100,-2) -> 3466100 | P15: =Q15-O15 -> 977600 | Q15: 4443700
... A28: 202210 | B28: 44855 | C28: 大麦 | D28: 81185477320 | E28: 350 | F28: =G28/E28 -> 54291.851 | G28: 19002148 | H28: 19002000 | I28: 1900100 | J28: 0 | K28: =ROUNDDOWN(H28*7.8/100,-2) -> 1482100 | L28: =I28-K28 -> 418000 | M28: 0 | N28: =ROUND(H28/E28*M28,-2) -> 0 | O28: =ROUNDDOWN(N28*7.8/100,-2) -> 0 | P28: =Q28-O28 -> 0 | Q28: 0
A29: 202210 | B29: 44855 | C29: メイズ | D29: 81185476400 | E29: =1000+900+830 -> 2730 | F29: =G29/E29 -> 49830.842 | G29: 136038199 | H29: 136038000 | I29: 13603700 | J29: 0 | K29: =ROUNDDOWN(H29*7.8/100,-2) -> 10610900 | L29: =I29-K29 -> 2992800 | M29: 830 | N29: =ROUND(H29/E29*M29,-2) -> 41359500 | O29: =ROUNDDOWN(N29*7.8/100,-2) -> 3226000 | P29: =Q29-O29 -> 909900 | Q29: 4135900
A30: 202211 | B30: 44867 | C30: 大麦 | D30: 81185678810 | E30: 525 | F30: =G30/E30 -> 64742.45 | G30: 33989786 | H30: 33989000 | I30: 3398800 | J30: 0 | K30: =ROUNDDOWN(H30*7.8/100,-2) -> 2651100 | L30: =I30-K30 -> 747700 | M30: 0 | N30: =ROUND(H30/E30*M30,-2) -> 0 | O30: =ROUNDDOWN(N30*7.8/100,-2) -> 0 | P30: =Q30-O30 -> 0 | Q30: 0
A31: 202211 | B31: 44880 | C31: 大麦 | D31: 81185941050 | E31: 1155 | F31: =G31/E31 -> 64222.397 | G31: 74176869 | H31: 74176000 | I31: 7417500 | J31: 0 | K31: =ROUNDDOWN(H31*7.8/100,-2) -> 5785700 | L31: =I31-K31 -> 1631800 | M31: 0 | N31: =ROUND(H31/E31*M31,-2) -> 0 | O31: =ROUNDDOWN(N31*7.8/100,-2) -> 0 | P31: =Q31-O31 -> 0 | Q31: 0
A32: 202211 | B32: 44882 | C32: メイズ | D32: 81185997420 | E32: 890 | F32: =G32/E32 -> 51791.283 | G32: 46094242 | H32: 46094000 | I32: 4609300 | J32: 0 | K32: =ROUNDDOWN(H32*7.8/100,-2) -> 3595300 | L32: =I32-K32 -> 1014000 | M32: 490 | N32: =ROUND(H32/E32*M32,-2) -> 25377600 | O32: =ROUNDDOWN(N32*7.8/100,-2) -> 1979400 | P32: =Q32-O32 -> 558300 | Q32: 2537700
A33: 202211 | B33: 44889 | C33: 大麦 | D33: 81186095530 | E33: 367.5 | F33: =G33/E33 -> 56829.771 | G33: 20884941 | H33: 20884000 | I33: 2088300 | J33: 0 | K33: =ROUNDDOWN(H33*7.8/100,-2) -> 1628900 | L33: =I33-K33 -> 459400 | M33: 367.5 | N33: =ROUND(H33/E33*M33,-2) -> 20884000 | O33: =ROUNDDOWN(N33*7.8/100,-2) -> 1628900 | P33: =Q33-O33 -> 459400 | Q33: 2088300
A34: 202211 | B34: 44890 | C34: メイズ | D34: 81186146300 | E34: 260 | F34: =G34/E34 -> 49735.996 | G34: 12931359 | H34: 12931000 | I34: 1293000 | J34: 0 | K34: =ROUNDDOWN(H34*7.8/100,-2) -> 1008600 | L34: =I34-K34 -> 284400 | M34: 0 | N34: =ROUND(H34/E34*M34,-2) -> 0 | O34: =ROUNDDOWN(N34*7.8/100,-2) -> 0 | P34: =Q34-O34 -> 0 | Q34: 0
A35: 202211 | B35: 44895 | C35: 大麦 | D35: 81186228530 | E35: 750 | F35: =G35/E35 -> 60599.349 | G35: 45449512 | H35: 45449000 | I35: 4544800 | J35: 0 | K35: =ROUNDDOWN(H35*7.8/100,-2) -> 3545000 | L35: =I35-K35 -> 999800 | M35: 0 | N35: =ROUND(H35/E35*M35,-2) -> 0 | O35: =ROUNDDOWN(N35*7.8/100,-2) -> 0 | P35: =Q35-O35 -> 0 | Q35: 0
A36: 202212 | B36: 44900 | C36: メイズ | D36: 81186297610 | E36: 2090 | F36: =G36/E36 -> 47859.808 | G36: 100026998 | H36: 100026000 | I36: 10002500 | J36: 0 | K36: =ROUNDDOWN(H36*7.8/100,-2) -> 7802000 | L36: =I36-K36 -> 2200500 | M36: 450 | N36: =ROUND(H36/E36*M36,-2) -> 21536700 | O36: =ROUNDDOWN(N36*7.8/100,-2) -> 1679800 | P36: =Q36-O36 -> 473800 | Q36: 2153600
A37: 202212 | B37: 44907 | C37: メイズ | D37: 81186436320 | E37: 800 | F37: =G37/E37 -> 47047.469 | G37: 37637975 | H37: 37637000 | I37: 3763500 | J37: 0 | K37: =ROUNDDOWN(H37*7.8/100,-2) -> 2935600 | L37: =I37-K37 -> 827900 | M37: 800 | N37: =ROUND(H37/E37*M37,-2) -> 37637000 | O37: =ROUNDDOWN(N37*7.8/100,-2) -> 2935600 | P37: =Q37-O37 -> 827900 | Q37: 3763500
A38: 202212 | B38: 44923 | C38: メイズ | D38: 81186728660 | E38: 900 | F38: =G38/E38 -> 50947.187 | G38: 45852468 | H38: 45852000 | I38: 4585100 | J38: 0 | K38: =ROUNDDOWN(H38*7.8/100,-2) -> 3576400 | L38: =I38-K38 -> 1008700 | M38: 0 | N38: =ROUND(H38/E38*M38,-2) -> 0 | O38: =ROUNDDOWN(N38*7.8/100,-2) -> 0 | P38: =Q38-O38 -> 0 | Q38: 0
A39: 202301 | B39: 44936 | C39: メイズ | D39: 81186816640 | E39: 400 | F39: =G39/E39 -> 49684.882 | G39: 19873953 | H39: 19873000 | I39: 1987100 | J39: 0 | K39: =ROUNDDOWN(H39*7.8/100,-2) -> 1550000 | L39: =I39-K39 -> 437100 | M39: 0 | N39: =ROUND(H39/E39*M39,-2) -> 0 | O39: =ROUNDDOWN(N39*7.8/100,-2) -> 0 | P39: =Q39-O39 -> 0 | Q39: 0
A40: 202301 | B40: 44950 | C40: 大麦 | D40: 81187133040 | E40: 346.5 | F40: =G40/E40 -> 43389.469 | G40: 15034451 | H40: 15034000 | I40: 1503300 | J40: 0 | K40: =ROUNDDOWN(H40*7.8/100,-2) -> 1172600 | L40: =I40-K40 -> 330700 | M40: 346.5 | N40: =ROUND(H40/E40*M40,-2) -> 15034000 | O40: =ROUNDDOWN(N40*7.8/100,-2) -> 1172600 | P40: =Q40-O40 -> 330700 | Q40: 1503300
A41: 202301 | B41: 44950 | C41: メイズ | D41: 81187140630 | E41: 2825 | F41: =G41/E41 -> 47403.009 | G41: 133913500 | H41: 133913000 | I41: 13391200 | J41: 0 | K41: =ROUNDDOWN(H41*7.8/100,-2) -> 10445200 | L41: =I41-K41 -> 2946000 | M41: 725 | N41: =ROUND(H41/E41*M41,-2) -> 34367100 | O41: =ROUNDDOWN(N41*7.8/100,-2) -> 2680600 | P41: =Q41-O41 -> 756100 | Q41: 3436700
... A51: 202303 | B51: 45016 | C51: 大麦 | D51: 81188338660 | E51: 700 | F51: =G51/E51 -> 42098.169 | G51: 29468718 | H51: 29468000 | I51: 2946700 | J51: 0 | K51: =ROUNDDOWN(H51*7.8/100,-2) -> 2298500 | L51: =I51-K51 -> 648200 | M51: 0 | N51: =ROUND(H51/E51*M51,-2) -> 0 | O51: =ROUNDDOWN(N51*7.8/100,-2) -> 0 | P51: =Q51-O51 -> 0 | Q51: 0
O52: =SUM(O4:O51) -> 47443700 | P52: =SUM(P4:P51) -> 13381350 | Q52: =SUM(Q4:Q51) -> 60825050

Sheet 消費税負担分2021
A3: 対象年月 | B3: 通関年月日 | C3: 原料名 | D3: 通関NO | E3: 全体数量 （MT） | F3: 単価/ｔ | G3: 申告価格 | H3: 消費税計算用 （100円以下切捨て） | I3: 消費税額 | J3: D関税 | K3: F消費税 （7.8％） | L3: A地方消費税 （22/78） | M3: B負担分 数量 （MT） | N3: 負担分の 申告価格 割り返し | O3: ①消費税 （7.8％） | P3: ②地方消費税 （22/78） | Q3: 消費税 負担額
A4: 202104 | B4: 44287 | C4: 大麦 | D4: 81173727450 | E4: 252 | F4: =G4/E4 -> 25424.762 | G4: 6407040 | H4: 6407000 | I4: 640600 | J4: 0 | K4: =ROUNDDOWN(H4*7.8/100,-2) -> 499700 | L4: =I4-K4 -> 140900 | M4: 252 | N4: =ROUND(H4/E4*M4,-2) -> 6407000 | O4: =ROUNDDOWN(N4*7.8/100,-2) -> 499700 | P4: =Q4-O4 -> 140900 | Q4: 640600
A5: 202104 | B5: 44295 | C5: メイズ | D5: 81173903850 | E5: 400 | F5: =G5/E5 -> 33612.848 | G5: 13445139 | H5: 13445000 | I5: 1344400 | J5: 0 | K5: =ROUNDDOWN(H5*7.8/100,-2) -> 1048700 | L5: =I5-K5 -> 295700 | M5: 0 | N5: =ROUND(H5/E5*M5,-2) -> 0 | O5: =ROUNDDOWN(N5*7.8/100,-2) -> 0 | P5: =Q5-O5 -> 0 | Q5: 0
A6: 202104 | B6: 44300 | C6: 大麦 | D6: 81174026830 | E6: 900.67 | F6: =G6/E6 -> 26271.377 | G6: 23661841 | H6: 23661000 | I6: 2366000 | J6: 0 | K6: =ROUNDDOWN(H6*7.8/100,-2) -> 1845500 | L6: =I6-K6 -> 520500 | M6: 0 | N6: =ROUND(H6/E6*M6,-2) -> 0 | O6: =ROUNDDOWN(N6*7.8/100,-2) -> 0 | P6: =Q6-O6 -> 0 | Q6: 0
A7: 202104 | B7: 44301 | C7: メイズ | D7: 81174049120 | E7: 1070 | F7: =G7/E7 -> 34055.171 | G7: 36439033 | H7: 36439000 | I7: 3643800 | J7: 0 | K7: =ROUNDDOWN(H7*7.8/100,-2) -> 2842200 | L7: =I7-K7 -> 801600 | M7: 410 | N7: =ROUND(H7/E7*M7,-2) -> 13962600 | O7: =ROUNDDOWN(N7*7.8/100,-2) -> 1089000 | P7: =Q7-O7 -> 307200 | Q7: 1396200
A8: 202104 | B8: 44308 | C8: 大麦 | D8: 81174203120 | E8: 399 | F8: =G8/E8 -> 26132.293 | G8: 10426785 | H8: 10426000 | I8: 1042500 | J8: 0 | K8: =ROUNDDOWN(H8*7.8/100,-2) -> 813200 | L8: =I8-K8 -> 229300 | M8: 0 | N8: =ROUND(H8/E8*M8,-2) -> 0 | O8: =ROUNDDOWN(N8*7.8/100,-2) -> 0 | P8: =Q8-O8 -> 0 | Q8: 0
A9: 202104 | B9: 44316 | C9: メイズ | D9: 81174381510 | E9: 1580 | F9: =G9/E9 -> 33647.272 | G9: 53162690 | H9: 53162000 | I9: 5316100 | J9: 0 | K9: =ROUNDDOWN(H9*7.8/100,-2) -> 4146600 | L9: =I9-K9 -> 1169500 | M9: 500 | N9: =ROUND(H9/E9*M9,-2) -> 16823400 | O9: =ROUNDDOWN(N9*7.8/100,-2) -> 1312200 | P9: =Q9-O9 -> 370100 | Q9: 1682300
A10: 202105 | B10: 44340 | C10: メイズ | D10: 81174878360 | E10: 1200 | F10: =G10/E10 -> 35007.069 | G10: 42008483 | H10: 42008000 | I10: 4200700 | J10: 0 | K10: =ROUNDDOWN(H10*7.8/100,-2) -> 3276600 | L10: =I10-K10 -> 924100 | M10: 400 | N10: =ROUND(H10/E10*M10,-2) -> 14002700 | O10: =ROUNDDOWN(N10*7.8/100,-2) -> 1092200 | P10: =Q10-O10 -> 308100 | Q10: 1400300
A11: 202105 | B11: 44342 | C11: メイズ | D11: 81174924930 | E11: 880 | F11: =G11/E11 -> 35007.068 | G11: 30806220 | H11: 30806000 | I11: 3080500 | J11: 0 | K11: =ROUNDDOWN(H11*7.8/100,-2) -> 2402800 | L11: =I11-K11 -> 677700 | M11: 430 | N11: =ROUND(H11/E11*M11,-2) -> 15052900 | O11: =ROUNDDOWN(N11*7.8/100,-2) -> 1174100 | P11: =Q11-O11 -> 331200 | Q11: 1505300
A12: 202105 | B12: 44344 | C12: 大麦 | D12: 81174981040 | E12: 1020 | F12: =G12/E12 -> 27562.12 | G12: 28113362 | H12: 28113000 | I12: 2811200 | J12: 0 | K12: =ROUNDDOWN(H12*7.8/100,-2) -> 2192800 | L12: =I12-K12 -> 618400 | M12: 0 | N12: =ROUND(H12/E12*M12,-2) -> 0 | O12: =ROUNDDOWN(N12*7.8/100,-2) -> 0 | P12: =Q12-O12 -> 0 | Q12: 0
A13: 202106 | B13: 44350 | C13: 大麦 | D13: 81175091640 | E13: 420 | F13: =G13/E13 -> 28617.76 | G13: 12019459 | H13: 12019000 | I13: 1201700 | J13: 0 | K13: =ROUNDDOWN(H13*7.8/100,-2) -> 937400 | L13: =I13-K13 -> 264300 | M13: 0 | N13: =ROUND(H13/E13*M13,-2) -> 0 | O13: =ROUNDDOWN(N13*7.8/100,-2) -> 0 | P13: =Q13-O13 -> 0 | Q13: 0
A14: 202106 | B14: 44354 | C14: 大麦 | D14: 81175170410 | E14: 252 | F14: =G14/E14 -> 28617.758 | G14: 7211675 | H14: 7211000 | I14: 721000 | J14: 0 | K14: =ROUNDDOWN(H14*7.8/100,-2) -> 562400 | L14: =I14-K14 -> 158600 | M14: 252 | N14: =ROUND(H14/E14*M14,-2) -> 7211000 | O14: =ROUNDDOWN(N14*7.8/100,-2) -> 562400 | P14: =Q14-O14 -> 158600 | Q14: 721000
A15: 202106 | B15: 44361 | C15: メイズ | D15: 81175308420 | E15: 1292 | F15: =G15/E15 -> 34218.236 | G15: 44209961 | H15: 44209000 | I15: 4420800 | J15: 0 | K15: =ROUNDDOWN(H15*7.8/100,-2) -> 3448300 | L15: =I15-K15 -> 972500 | M15: 892 | N15: =ROUND(H15/E15*M15,-2) -> 30522000 | O15: =ROUNDDOWN(N15*7.8/100,-2) -> 2380700 | P15: =Q15-O15 -> 671400 | Q15: 3052100
... A52: 202203 | B52: 44636 | C52: メイズ | D52: 81180910040 | E52: 1900 | F52: =G52/E52 -> 38245.144 | G52: 72665774 | H52: 72665000 | I52: 7266400 | J52: 0 | K52: =ROUNDDOWN(H52*7.8/100,-2) -> 5667800 | L52: =I52-K52 -> 1598600 | M52: 0 | N52: =ROUND(H52/E52*M52,-2) -> 0 | O52: =ROUNDDOWN(N52*7.8/100,-2) -> 0 | P52: =Q52-O52 -> 0 | Q52: 0
O53: =SUM(O4:O52) -> 31440900 | P53: =SUM(P4:P52) -> 8867850 | Q53: =SUM(Q4:Q52) -> 40308750

Sheet 仮払い消費税（雪印） 2020
A1: 対象年月 | B1: 対象年月日 | C1: 原料名 | D1: 通関NO | E1: 全体数量 （MT） | F1: A 申告価格 | G1: 単価/ｔ | H1: A 消費税額 | I1: ①消費税 （7.8％） | J1: ②地方消費税 （22/78） | K1: B負担分 数量 （MT） | L1: 負担分の 申告価格 割り返し | M1: ①消費税 （7.8％） | N1: ②地方消費税 （22/78） | O1: 消費税 負担額
A2: 202004 | B2: 43923 | C2: メイズ | D2: 81165843610 | E2: 30 | F2: 712230 | G2: =F2/E2 -> 23741 | H2: 71100 | I2: 55500 | J2: =H2-I2 -> 15600 | K2: 30 | L2: =ROUND(F2/E2*K2,-2) -> 712200 | M2: =ROUNDDOWN(L2*7.8/100,-2) -> 55500 | N2: =O2-M2 -> 15600 | O2: 71100
A3: 202004 | B3: 43937 | C3: メイズ | D3: 81166181120 | E3: 710 | F3: 16810770 | G3: =F3/E3 -> 23677.141 | H3: 1680800 | I3: 1311100 | J3: =H3-I3 -> 369700 | K3: 210 | L3: =ROUND(F3/E3*K3,-2) -> 4972200 | M3: =ROUNDDOWN(L3*7.8/100,-2) -> 387800 | N3: =O3-M3 -> 109300 | O3: 497100
A4: 202005 | B4: 43962 | C4: メイズ | D4: 81166709360 | E4: 1860 | F4: 44335517 | G4: =F4/E4 -> 23836.299 | H4: 4433400 | I4: 3458100 | J4: =H4-I4 -> 975300 | K4: 710 | L4: =ROUND(F4/E4*K4,-2) -> 16923800 | M4: =ROUNDDOWN(L4*7.8/100,-2) -> 1320000 | N4: =O4-M4 -> 372300 | O4: 1692300
A5: 202005 | B5: 43970 | C5: 大麦 | D5: 81166962910 | E5: 273 | F5: 6738717 | G5: =F5/E5 -> 24683.945 | H5: 673700 | I5: 525500 | J5: =H5-I5 -> 148200 | K5: 273 | L5: =ROUND(F5/E5*K5,-2) -> 6738700 | M5: =ROUNDDOWN(L5*7.8/100,-2)-100 -> 525500 | N5: =O5-M5 -> 148200 | O5: 673700
A6: 202006 | B6: 43984 | C6: メイズ | D6: 81167269400 | E6: 1550 | F6: 32562163 | G6: =F6/E6 -> 21007.847 | H6: 3256100 | I6: 2539800 | J6: =H6-I6 -> 716300 | K6: 500 | L6: =ROUND(F6/E6*K6,-2) -> 10503900 | M6: =ROUNDDOWN(L6*7.8/100,-2) -> 819300 | N6: =O6-M6 -> 231100 | O6: 1050400
A7: 202006 | B7: 43984 | C7: メイズ | D7: 81167269510 | E7: 260 | F7: 5358313 | G7: =F7/E7 -> 20608.896 | H7: 535700 | I7: 417900 | J7: =H7-I7 -> 117800 | K7: 260 | L7: =ROUND(F7/E7*K7,-2) -> 5358300 | M7: =ROUNDDOWN(L7*7.8/100,-2) -> 417900 | N7: =O7-M7 -> 117800 | O7: 535700
A8: 202006 | B8: 43999 | C8: メイズ | D8: 81167661950 | E8: 1590 | F8: 34028642 | G8: =F8/E8 -> 21401.662 | H8: 3402600 | I8: 2654100 | J8: =H8-I8 -> 748500 | K8: 460 | L8: =ROUND(F8/E8*K8,-2) -> 9844800 | M8: =ROUNDDOWN(L8*7.8/100,-2) -> 767800 | N8: =O8-M8 -> 216600 | O8: 984400
A9: 202007 | B9: 44018 | C9: 大麦 | D9: 81168066220 | E9: 210 | F9: 4750495 | G9: =F9/E9 -> 22621.405 | H9: 475000 | I9: =ROUNDUP(H9*0.78,-1) -> 370500 | J9: =H9-I9 -> 104500 | K9: 210 | L9: =ROUND(F9/E9*K9,-2) -> 4750500 | M9: =ROUNDDOWN(L9*7.8/100,-2) -> 370500 | N9: =O9-M9 -> 104500 | O9: 475000
A10: 202007 | B10: 44021 | C10: メイズ | D10: 81168162560 | E10: 1460 | F10: 29699835 | G10: =F10/E10 -> 20342.353 | H10: 2969800 | I10: 2316500 | J10: =H10-I10 -> 653300 | K10: 450 | L10: =ROUND(F10/E10*K10,-2) -> 9154100 | M10: =ROUNDDOWN(L10*7.8/100,-2) -> 714000 | N10: =O10-M10 -> 201300 | O10: 915300
A11: 202007 | B11: 44039 | C11: メイズ | D11: 81168485410 | E11: 1420 | F11: 27096653 | G11: =F11/E11 -> 19082.15 | H11: 2709400 | I11: 2113400 | J11: =H11-I11 -> 596000 | K11: 590 | L11: =ROUND(F11/E11*K11,-2) -> 11258500 | M11: =ROUNDDOWN(L11*7.8/100,-2) -> 878100 | N11: =O11-M11 -> 247700 | O11: 1125800
A12: 202008 | B12: 44061 | C12: メイズ | D12: 81168949250 | E12: 1230 | F12: 24253935 | G12: =F12/E12 -> 19718.646 | H12: 2425200 | I12: 1891700 | J12: =H12-I12 -> 533500 | K12: 360 | L12: =ROUND(F12/E12*K12,-2) -> 7098700 | M12: =ROUNDDOWN(L12*7.8/100,-2) -> 553600 | N12: =O12-M12 -> 156200 | O12: 709800
A13: 202009 | B13: 44085 | C13: メイズ | D13: 81169543920 | E13: 1760 | F13: 35652041 | G13: =F13/E13 -> 20256.841 | H13: 3565100 | I13: 2780800 | J13: =H13-I13 -> 784300 | K13: 530 | L13: =ROUND(F13/E13*K13,-2) -> 10736100 | M13: =ROUNDDOWN(L13*7.8/100,-2) -> 837400 | N13: =O13-M13 -> 236200 | O13: 1073600
A14: 202009 | B14: 44103 | C14: 大麦 | D14: 81169873400 | E14: 126 | F14: 3011492 | G14: =F14/E14 -> 23900.73 | H14: 301000 | I14: 234800 | J14: =H14-I14 -> 66200 | K14: 126 | L14: =ROUND(F14/E14*K14,-2) -> 3011500 | M14: =ROUNDDOWN(L14*7.8/100,-2) -> 234800 | N14: =O14-M14 -> 66200 | O14: 301000
A15: 202010 | B15: 44109 | C15: メイズ | D15: 81169997300 | E15: 1670 | F15: 33519985 | G15: =F15/E15 -> 20071.847 | H15: 3351700 | I15: 2614400 | J15: =H15-I15 -> 737300 | K15: 600 | L15: =ROUND(F15/E15*K15,-2) -> 12043100 | M15: =ROUNDDOWN(L15*7.8/100,-2) -> 939300 | N15: =O15-M15 -> 264900 | O15: 1204200
A16: 202010 | B16: 44127 | C16: メイズ | D16: 81170424520 | E16: 1660 | F16: 32776955 | G16: =F16/E16 -> 19745.154 | H16: 3277500 | I16: 2556500 | J16: =H16-I16 -> 721000 | K16: 520 | L16: =ROUND(F16/E16*K16,-2) -> 10267500 | M16: =ROUNDDOWN(L16*7.8/100,-2) -> 800800 | N16: =O16-M16 -> 225900 | O16: 1026700
A17: 202011 | B17: 44152 | C17: メイズ | D17: 81170971110 | E17: 1780 | F17: 36603386 | G17: =F17/E17 -> 20563.7 | H17: 3660200 | I17: =ROUNDUP(H17*0.78,-1) -> 2854960 | J17: =H17-I17 -> 805240 | K17: 630 | L17: =ROUND(F17/E17*K17,-2) -> 12955100 | M17: =ROUNDDOWN(L17*7.8/100,-2) -> 1010400 | N17: =O17-M17 -> 285100 | O17: 1295500
A18: 202011 | B18: 44154 | C18: 大麦 | D18: 81171033300 | E18: 220 | F18: 5141565 | G18: =F18/E18 -> 23370.75 | H18: 513900 | I18: 400900 | J18: =H18-I18 -> 113000 | K18: 220 | L18: =ROUND(F18/E18*K18,-2) -> 5141600 | M18: 400900 | N18: =O18-M18 -> 113000 | O18: 513900
A19: 202012 | B19: 44172 | C19: メイズ | D19: 81171393760 | E19: 350 | F19: 7744988 | G19: =F19/E19 -> 22128.537 | H19: 774300 | I19: 604000 | J19: =H19-I19 -> 170300 | K19: 200 | L19: =ROUND(F19/E19*K19,-2) -> 4425700 | M19: =ROUNDDOWN(L19*7.8/100,-2) -> 345200 | N19: =O19-M19 -> 97300 | O19: 442500
A20: 202012 | B20: 44175 | C20: メイズ | D20: 81171493310 | E20: 1230 | F20: 27218105 | G20: =F20/E20 -> 22128.541 | H20: 2721700 | I20: 2123000 | J20: =H20-I20 -> 598700 | K20: 480 | L20: =ROUND(F20/E20*K20,-2) -> 10621700 | M20: =ROUNDDOWN(L20*7.8/100,-2) -> 828400 | N20: =O20-M20 -> 233800 | O20: 1062200
A21: 202012 | B21: 44189 | C21: メイズ | D21: 81171766530 | E21: 2030 | F21: 44092225 | G21: =F21/E21 -> 21720.308 | H21: 4409100 | I21: =ROUNDUP(H21*0.78,-1) -> 3439100 | J21: =H21-I21 -> 970000 | K21: 550 | L21: =ROUND(F21/E21*K21,-2) -> 11946200 | M21: =ROUNDDOWN(L21*7.8/100,-2) -> 931800 | N21: =O21-M21 -> 262800 | O21: 1194600
A22: 202101 | B22: 44218 | C22: メイズ | D22: 81172250450 | E22: 900 | F22: 22552516 | G22: =F22/E22 -> 25058.351 | H22: 2255100 | I22: 1759000 | J22: =H22-I22 -> 496100 | K22: 475 | L22: =ROUND(F22/E22*K22,-2) -> 11902700 | M22: =ROUNDDOWN(L22*7.8/100,-2) -> 928400 | N22: =O22-M22 -> 261800 | O22: 1190200
A23: 202101 | B23: 44224 | C23: メイズ | D23: 81172388460 | E23: 1700 | F23: 42902698 | G23: =F23/E23 -> 25236.881 | H23: 4290100 | I23: 3346300 | J23: =H23-I23 -> 943800 | K23: 475 | L23: =ROUND(F23/E23*K23,-2) -> 11987500 | M23: =ROUNDDOWN(L23*7.8/100,-2) -> 935000 | N23: =O23-M23 -> 263700 | O23: 1198700
A24: 202102 | B24: 44228 | C24: 大麦 | D24: 81172451350 | E24: 231 | F24: 5266206 | G24: =F24/E24 -> 22797.429 | H24: 526500 | I24: 410700 | J24: =H24-I24 -> 115800 | K24: 231 | L24: =ROUND(F24/E24*K24,-2) -> 5266200 | M24: =ROUNDDOWN(L24*7.8/100,-2) -> 410700 | N24: =O24-M24 -> 115800 | O24: 526500
A25: 202102 | B25: 44249 | C25: メイズ | D25: 81172878940 | E25: 1870 | F25: 51610414 | G25: =F25/E25 -> 27599.152 | H25: 5160800 | I25: 4025500 | J25: =H25-I25 -> 1135300 | K25: 570 | L25: =ROUND(F25/E25*K25,-2) -> 15731500 | M25: =ROUNDDOWN(L25*7.8/100,-2) -> 1227000 | N25: =O25-M25 -> 346100 | O25: 1573100
A26: 202103 | B26: 44265 | C26: メイズ | D26: 81173191360 | E26: 240 | F26: 6114206 | G26: =F26/E26 -> 25475.858 | H26: 611200 | I26: 476800 | J26: =H26-I26 -> 134400 | K26: 100 | L26: =ROUND(F26/E26*K26,-2) -> 2547600 | M26: =ROUNDDOWN(L26*7.8/100,-2) -> 198700 | N26: =O26-M26 -> 56000 | O26: 254700
A27: 202103 | B27: 44274 | C27: メイズ | D27: 81173420520 | E27: 930 | F27: 29045942 | G27: =F27/E27 -> 31232.196 | H27: 2904400 | I27: 2265500 | J27: =H27-I27 -> 638900 | K27: 330 | L27: =ROUND(F27/E27*K27,-2) -> 10306600 | M27: =ROUNDDOWN(L27*7.8/100,-2) -> 803900 | N27: =O27-M27 -> 226700 | O27: 1030600
A28: 202103 | B28: 44284 | C28: メイズ | D28: 81173607200 | E28: 1080 | F28: 31565504 | G28: =F28/E28 -> 29227.319 | H28: 3156400 | I28: =ROUNDUP(H28*0.78,-1) -> 2462000 | J28: =H28-I28 -> 694400 | K28: 390 | L28: =ROUND(F28/E28*K28,-2) -> 11398700 | M28: =ROUNDDOWN(L28*7.8/100,-2) -> 889000 | N28: =O28-M28 -> 250800 | O28: 1139800
M29: =SUM(M2:M28) -> 18531700 | N29: =SUM(N2:N28) -> 5226700 | O29: =SUM(O2:O28) -> 23758400

Sheet 仮払い消費税（雪印）2019
A1: 対象年月 | B1: 対象年月日 | C1: 原料名 | D1: 数量（ｔ） | E1: 通関NO | F1: 消費税額 | G1: ①消費税 （78.75％） | H1: ②地方消費税 （21.25％）
A2: 201904 | B2: 43571 | C2: 大麦 | D2: 400 | E2: 81158201930 | F2: 937600 | G2: =ROUNDUP(F2*0.7875,-1) -> 738360 | H2: =F2-G2 -> 199240
A3: 201904 | B3: 43572 | C3: メイズ | D3: 600 | E3: 81158220130 | F3: 1162400 | G3: =ROUNDUP(F3*0.7875,-1) -> 915390 | H3: =F3-G3 -> 247010
A4: 201904 | B4: 43585 | C4: メイズ | D4: 300 | E4: 81158476440 | F4: 574400 | G4: =ROUNDUP(F4*0.7875,-1) -> 452340 | H4: =F4-G4 -> 122060
A5: 月計 | F5: =SUM(F2:F4) -> 2674400 | G5: =ROUNDDOWN(F5*0.7875,0) -> 2106090 | H5: =F5-G5 -> 568310
A6: 201905 | B6: 43600 | C6: メイズ | D6: 450 | E6: 81158790630 | F6: 862200 | G6: =ROUNDUP(F6*0.7875,-1) -> 678990 | H6: =F6-G6 -> 183210
A7: 201905 | B7: 43608 | C7: メイズ | D7: 370 | E7: 81158979520 | F7: 678100 | G7: =ROUNDUP(F7*0.7875,-1) -> 534010 | H7: =F7-G7 -> 144090
A8: 月計 | F8: =SUM(F6:F7) -> 1540300 | G8: =ROUNDDOWN(F8*0.7875,0) -> 1212986 | H8: =F8-G8 -> 327314
A9: 201906 | B9: 43619 | C9: メイズ | D9: 200 | E9: 81159202450 | F9: 363400 | G9: =ROUNDUP(F9*0.7875,-1) -> 286180 | H9: =F9-G9 -> 77220
A10: 201906 | B10: 43637 | C10: メイズ | D10: 2030 | E10: 81159651040 | F10: 3790700 | G10: =ROUNDUP(F10*0.7875,-1) -> 2985180 | H10: =F10-G10 -> 805520
A11: 201906 | B11: 43643 | C11: 大麦 | D11: 280 | E11: 81159779950 | F11: 646000 | G11: =ROUNDUP(F11*0.7875,-1) -> 508730 | H11: =F11-G11 -> 137270
A12: 201906 | G12: =ROUNDUP(F12*0.7875,-1) -> 0 | H12: =F12-G12 -> 0
A13: 201906 | G13: =ROUNDUP(F13*0.7875,-1) -> 0 | H13: =F13-G13 -> 0
A14: 月計 | F14: =SUM(F9:F13) -> 4800100 | G14: =ROUNDDOWN(F14*0.7875,0) -> 3780078 | H14: =F14-G14 -> 1020022
A15: 201907 | G15: =ROUNDUP(F15*0.7875,-1) -> 0 | H15: =F15-G15 -> 0
A16: 201907 | G16: =ROUNDUP(F16*0.7875,-1) -> 0 | H16: =F16-G16 -> 0
A17: 月計 | F17: =SUM(F15:F16) -> 0 | G17: =ROUNDDOWN(F17*0.7875,0) -> 0 | H17: =F17-G17 -> 0
A18: 201908 | B18: 43693 | C18: メイズ | D18: 320 | E18: 81160892950 | F18: 607400 | G18: =ROUNDUP(F18*0.7875,-1) -> 478330 | H18: =F18-G18 -> 129070
A19: 201908 | B19: 43706 | C19: メイズ | D19: 610 | E19: 81161232930 | F19: 1202800 | G19: =ROUNDUP(F19*0.7875,-1) -> 947210 | H19: =F19-G19 -> 255590
A20: 201908 | G20: =ROUNDUP(F20*0.7875,-1) -> 0 | H20: =F20-G20 -> 0
A21: 201908 | G21: =ROUNDUP(F21*0.7875,-1) -> 0 | H21: =F21-G21 -> 0
A22: 201908 | G22: =ROUNDUP(F22*0.7875,-1) -> 0 | H22: =F22-G22 -> 0
A23: 月計 | F23: =SUM(F18:F22) -> 1810200 | G23: =ROUNDDOWN(F23*0.7875,0) -> 1425532 | H23: =F23-G23 -> 384668
A24: 201909 | B24: 43714 | C24: 大麦 | D24: 320 | E24: 81161395220 | F24: 672300 | G24: =ROUNDUP(F24*0.7875,-1) -> 529440 | H24: =F24-G24 -> 142860
A25: 201909 | B25: 43728 | C25: メイズ | D25: 480 | E25: 81161704730 | F25: 807900 | G25: =ROUNDUP(F25*0.7875,-1) -> 636230 | H25: =F25-G25 -> 171670
A26: 201909 | G26: =ROUNDUP(F26*0.7875,-1) -> 0 | H26: =F26-G26 -> 0
A27: 201909 | G27: =ROUNDUP(F27*0.7875,-1) -> 0 | H27: =F27-G27 -> 0
A28: 201909 | G28: =ROUNDUP(F28*0.7875,-1) -> 0 | H28: =F28-G28 -> 0
A29: 月計 | F29: =SUM(F24:F28) -> 1480200 | G29: =ROUNDDOWN(F29*0.7875,0) -> 1165657 | H29: =F29-G29 -> 314543
A30: 201910 | B30: 43745 | C30: メイズ | D30: 610 | E30: 81162023340 | F30: 1389600 | G30: =ROUNDUP(F30*0.7875,-1) -> 1094310 | H30: =F30-G30 -> 295290
A31: 201910 | B31: 43753 | C31: 大麦 | D31: 367.5 | E31: 81162180620 | F31: 946700 | G31: =ROUNDUP(F31*0.7875,-1) -> 745530 | H31: =F31-G31 -> 201170
A32: 201910 | B32: 43769 | C32: メイズ | D32: 470 | E32: 81162564330 | F32: 1111300 | G32: =ROUNDUP(F32*0.7875,-1) -> 875150 | H32: =F32-G32 -> 236150
A33: 201910 | G33: =ROUNDUP(F33*0.7875,-1) -> 0 | H33: =F33-G33 -> 0
A34: 201910 | G34: =ROUNDUP(F34*0.7875,-1) -> 0 | H34: =F34-G34 -> 0
A35: 月計 | F35: =SUM(F30:F34) -> 3447600 | G35: =ROUNDDOWN(F35*0.7875,0) -> 2714985 | H35: =F35-G35 -> 732615
A36: 201911 | B36: 43789 | C36: メイズ | D36: 690 | E36: 81163019700 | F36: 1456300 | G36: =ROUNDUP(F36*0.7875,-1) -> 1146840 | H36: =F36-G36 -> 309460
A37: 201911 | G37: =ROUNDUP(F37*0.7875,-1) -> 0 | H37: =F37-G37 -> 0
A38: 201911 | G38: =ROUNDUP(F38*0.7875,-1) -> 0 | H38: =F38-G38 -> 0
A39: 月計 | F39: =SUM(F36:F38) -> 1456300 | G39: =ROUNDDOWN(F39*0.7875,0) -> 1146836 | H39: =F39-G39 -> 309464
A40: 201912 | B40: 43803 | C40: メイズ | D40: 530 | E40: 81163317860 | F40: 1244200 | G40: =ROUNDUP(F40*0.7875,-1) -> 979810 | H40: =F40-G40 -> 264390
...

Sheet メイズ消費税（雪印）マイナス
C1: v
A4: 請 求 書
J7: NO. | L7: 503
J9: 39756
C13: 雪印種苗株式会社 | E13: 御中
J16: TEL | L16: (0178)21-3353(代表)
J17: FAX | L17: (0178)29-1300
C19: 下記の通り御請求申し上げます
B21: 月 | C21: 日 | D21: 品 名 | E21: 区分 | F21: 数量 | H21: 総量（kg） | J21: 単 価 | L21: 金 額（円）
B22: ='輸入品消費税（日和産業）'!B21:C21 -> 8月分 | D22: 輸入品消費税
